Workbook

Sheet COMO USAR
A1: CONTROLE DE DECKS — DIGIMON TCG
A3: Cada pessoa deve usar a SUA PRÓPRIA CÓPIA desta planilha (Arquivo > Fazer uma cópia), porque o inventário e as compras são pessoais.
A4: Células amarelo-claro com texto azul = onde você escreve. Todo o resto é calculado e fica protegido.
A6: 1) PRIMEIRA VEZ (uma vez por cópia)
A7: Extensões > Apps Script > cole o conteúdo do arquivo configurar_planilha.gs > Salvar > recarregue a planilha > menu Digimon > Configurar planilha.
A8: Isso liga as fotos e trava as células que não devem ser editadas. Autorize o script quando o Google pedir.
A10: 2) ADICIONAR UM DECK (aba LISTAS)
A11: No digimoncard.io: abra o deck > Export > Text > Copy to Clipboard. Ou copie a lista da Liga Digimon.
A12: Na primeira coluna livre da aba LISTAS: escreva o nome do deck (linha 1), o link (linha 2) e cole a lista a partir da linha 4.
A13: Os dois formatos funcionam: 1 BanchoMamemon BT8-068 e 4 Chuumon (EX13-027)
A14: A linha 3 mostra quantas linhas e cartas foram lidas e avisa se alguma linha foi ignorada. Linhas que começam com // são comentários.
A15: Capacidade: 20 decks, até 60 linhas cada.
... A39: Para subir fotos novas: aba Update de Fotos > menu Digimon > Verificar fotos no repositório > copie a lista em Python e cole no script do repositório.

Sheet CONFIG
A1: CONFIGURAÇÃO DAS FOTOS
A2: Endereço base das imagens | B2: https://raw.githubusercontent.com/matheusabarbosa/digimon-cg-2020-cards/main/digimon/cartas/ | C2: Repositório de imagens no GitHub. Deve terminar com /
A3: Extensão das imagens | B3: .jpg | C3: Normalmente .jpg
A4: Mostrar fotos? (SIM/NÃO) | B4: SIM | C4: Mude para NÃO para desligar as fotos (a planilha fica mais leve)
A5: Altura da foto (pixels) | B5: 200 | C5: Altura das linhas que têm foto

Sheet LISTAS
A3: =IF(COUNTA(A4:A63)=0,"",COUNTIFS(_LEITURA!$A$2:$A$1201,1,_LEITURA!$I$2:$I$1201,1)&" linhas lidas · "&SUMIFS(_LEITURA!$G$2:$G$1201,_LEITURA!$A$2:$A$1201,1,_LEITURA!$I$2:$I$1201,1)&" cartas"&IF(COUNTIFS(_LEITURA!$A$2:$A$1201,1,_LEITURA!$L$2:$L$1201,1)>0," · ATENÇÃO: "&COUNTIFS(_LEITURA!$A$2:$A$1201,1,_LEITURA!$L$2:$L$1201,1)&" linha(s) ignorada(s)","")) | B3: =IF(COUNTA(B4:B63)=0,"",COUNTIFS(_LEITURA!$A$2:$A$1201,2,_LEITURA!$I$2:$I$1201,1)&" linhas lidas · "&SUMIFS(_LEITURA!$G$2:$G$1201,_LEITURA!$A$2:$A$1201,2,_LEITURA!$I$2:$I$1201,1)&" cartas"&IF(COUNTIFS(_LEITURA!$A$2:$A$1201,2,_LEITURA!$L$2:$L$1201,1)>0," · ATENÇÃO: "&COUNTIFS(_LEITURA!$A$2:$A$1201,2,_LEITURA!$L$2:$L$1201,1)&" linha(s) ignorada(s)","")) | C3: =IF(COUNTA(C4:C63)=0,"",COUNTIFS(_LEITURA!$A$2:$A$1201,3,_LEITURA!$I$2:$I$1201,1)&" linhas lidas · "&SUMIFS(_LEITURA!$G$2:$G$1201,_LEITURA!$A$2:$A$1201,3,_LEITURA!$I$2:$I$1201,1)&" cartas"&IF(COUNTIFS(_LEITURA!$A$2:$A$1201,3,_LEITURA!$L$2:$L$1201,1)>0," · ATENÇÃO: "&COUNTIFS(_LEITURA!$A$2:$A$1201,3,_LEITURA!$L$2:$L$1201,1)&" linha(s) ignorada(s)","")) | D3: =IF(COUNTA(D4:D63)=0,"",COUNTIFS(_LEITURA!$A$2:$A$1201,4,_LEITURA!$I$2:$I$1201,1)&" linhas lidas · "&SUMIFS(_LEITURA!$G$2:$G$1201,_LEITURA!$A$2:$A$1201,4,_LEITURA!$I$2:$I$1201,1)&" cartas"&IF(COUNTIFS(_LEITURA!$A$2:$A$1201,4,_LEITURA!$L$2:$L$1201,1)>0," · ATENÇÃO: "&COUNTIFS(_LEITURA!$A$2:$A$1201,4,_LEITURA!$L$2:$L$1201,1)&" linha(s) ignorada(s)","")) | E3: =IF(COUNTA(E4:E63)=0,"",COUNTIFS(_LEITURA!$A$2:$A$1201,5,_LEITURA!$I$2:$I$1201,1)&" linhas lidas · "&SUMIFS(_LEITURA!$G$2:$G$1201,_LEITURA!$A$2:$A$1201,5,_LEITURA!$I$2:$I$1201,1)&" cartas"&IF(COUNTIFS(_LEITURA!$A$2:$A$1201,5,_LEITURA!$L$2:$L$1201,1)>0," · ATENÇÃO: "&COUNTIFS(_LEITURA!$A$2:$A$1201,5,_LEITURA!$L$2:$L$1201,1)&" linha(s) ignorada(s)","")) | F3: =IF(COUNTA(F4:F63)=0,"",COUNTIFS(_LEITURA!$A$2:$A$1201,6,_LEITURA!$I$2:$I$1201,1)&" linhas lidas · "&SUMIFS(_LEITURA!$G$2:$G$1201,_LEITURA!$A$2:$A$1201,6,_LEITURA!$I$2:$I$1201,1)&" cartas"&IF(COUNTIFS(_LEITURA!$A$2:$A$1201,6,_LEITURA!$L$2:$L$1201,1)>0," · ATENÇÃO: "&COUNTIFS(_LEITURA!$A$2:$A$1201,6,_LEITURA!$L$2:$L$1201,1)&" linha(s) ignorada(s)","")) | G3: =IF(COUNTA(G4:G63)=0,"",COUNTIFS(_LEITURA!$A$2:$A$1201,7,_LEITURA!$I$2:$I$1201,1)&" linhas lidas · "&SUMIFS(_LEITURA!$G$2:$G$1201,_LEITURA!$A$2:$A$1201,7,_LEITURA!$I$2:$I$1201,1)&" cartas"&IF(COUNTIFS(_LEITURA!$A$2:$A$1201,7,_LEITURA!$L$2:$L$1201,1)>0," · ATENÇÃO: "&COUNTIFS(_LEITURA!$A$2:$A$1201,7,_LEITURA!$L$2:$L$1201,1)&" linha(s) ignorada(s)","")) | H3: =IF(COUNTA(H4:H63)=0,"",COUNTIFS(_LEITURA!$A$2:$A$1201,8,_LEITURA!$I$2:$I$1201,1)&" linhas lidas · "&SUMIFS(_LEITURA!$G$2:$G$1201,_LEITURA!$A$2:$A$1201,8,_LEITURA!$I$2:$I$1201,1)&" cartas"&IF(COUNTIFS(_LEITURA!$A$2:$A$1201,8,_LEITURA!$L$2:$L$1201,1)>0," · ATENÇÃO: "&COUNTIFS(_LEITURA!$A$2:$A$1201,8,_LEITURA!$L$2:$L$1201,1)&" linha(s) ignorada(s)","")) | I3: =IF(COUNTA(I4:I63)=0,"",COUNTIFS(_LEITURA!$A$2:$A$1201,9,_LEITURA!$I$2:$I$1201,1)&" linhas lidas · "&SUMIFS(_LEITURA!$G$2:$G$1201,_LEITURA!$A$2:$A$1201,9,_LEITURA!$I$2:$I$1201,1)&" cartas"&IF(COUNTIFS(_LEITURA!$A$2:$A$1201,9,_LEITURA!$L$2:$L$1201,1)>0," · ATENÇÃO: "&COUNTIFS(_LEITURA!$A$2:$A$1201,9,_LEITURA!$L$2:$L$1201,1)&" linha(s) ignorada(s)","")) | J3: =IF(COUNTA(J4:J63)=0,"",COUNTIFS(_LEITURA!$A$2:$A$1201,10,_LEITURA!$I$2:$I$1201,1)&" linhas lidas · "&SUMIFS(_LEITURA!$G$2:$G$1201,_LEITURA!$A$2:$A$1201,10,_LEITURA!$I$2:$I$1201,1)&" cartas"&IF(COUNTIFS(_LEITURA!$A$2:$A$1201,10,_LEITURA!$L$2:$L$1201,1)>0," · ATENÇÃO: "&COUNTIFS(_LEITURA!$A$2:$A$1201,10,_LEITURA!$L$2:$L$1201,1)&" linha(s) ignorada(s)","")) | K3: =IF(COUNTA(K4:K63)=0,"",COUNTIFS(_LEITURA!$A$2:$A$1201,11,_LEITURA!$I$2:$I$1201,1)&" linhas lidas · "&SUMIFS(_LEITURA!$G$2:$G$1201,_LEITURA!$A$2:$A$1201,11,_LEITURA!$I$2:$I$1201,1)&" cartas"&IF(COUNTIFS(_LEITURA!$A$2:$A$1201,11,_LEITURA!$L$2:$L$1201,1)>0," · ATENÇÃO: "&COUNTIFS(_LEITURA!$A$2:$A$1201,11,_LEITURA!$L$2:$L$1201,1)&" linha(s) ignorada(s)","")) | L3: =IF(COUNTA(L4:L63)=0,"",COUNTIFS(_LEITURA!$A$2:$A$1201,12,_LEITURA!$I$2:$I$1201,1)&" linhas lidas · "&SUMIFS(_LEITURA!$G$2:$G$1201,_LEITURA!$A$2:$A$1201,12,_LEITURA!$I$2:$I$1201,1)&" cartas"&IF(COUNTIFS(_LEITURA!$A$2:$A$1201,12,_LEITURA!$L$2:$L$1201,1)>0," · ATENÇÃO: "&COUNTIFS(_LEITURA!$A$2:$A$1201,12,_LEITURA!$L$2:$L$1201,1)&" linha(s) ignorada(s)","")) | M3: =IF(COUNTA(M4:M63)=0,"",COUNTIFS(_LEITURA!$A$2:$A$1201,13,_LEITURA!$I$2:$I$1201,1)&" linhas lidas · "&SUMIFS(_LEITURA!$G$2:$G$1201,_LEITURA!$A$2:$A$1201,13,_LEITURA!$I$2:$I$1201,1)&" cartas"&IF(COUNTIFS(_LEITURA!$A$2:$A$1201,13,_LEITURA!$L$2:$L$1201,1)>0," · ATENÇÃO: "&COUNTIFS(_LEITURA!$A$2:$A$1201,13,_LEITURA!$L$2:$L$1201,1)&" linha(s) ignorada(s)","")) | N3: =IF(COUNTA(N4:N63)=0,"",COUNTIFS(_LEITURA!$A$2:$A$1201,14,_LEITURA!$I$2:$I$1201,1)&" linhas lidas · "&SUMIFS(_LEITURA!$G$2:$G$1201,_LEITURA!$A$2:$A$1201,14,_LEITURA!$I$2:$I$1201,1)&" cartas"&IF(COUNTIFS(_LEITURA!$A$2:$A$1201,14,_LEITURA!$L$2:$L$1201,1)>0," · ATENÇÃO: "&COUNTIFS(_LEITURA!$A$2:$A$1201,14,_LEITURA!$L$2:$L$1201,1)&" linha(s) ignorada(s)","")) | O3: =IF(COUNTA(O4:O63)=0,"",COUNTIFS(_LEITURA!$A$2:$A$1201,15,_LEITURA!$I$2:$I$1201,1)&" linhas lidas · "&SUMIFS(_LEITURA!$G$2:$G$1201,_LEITURA!$A$2:$A$1201,15,_LEITURA!$I$2:$I$1201,1)&" cartas"&IF(COUNTIFS(_LEITURA!$A$2:$A$1201,15,_LEITURA!$L$2:$L$1201,1)>0," · ATENÇÃO: "&COUNTIFS(_LEITURA!$A$2:$A$1201,15,_LEITURA!$L$2:$L$1201,1)&" linha(s) ignorada(s)","")) | P3: =IF(COUNTA(P4:P63)=0,"",COUNTIFS(_LEITURA!$A$2:$A$1201,16,_LEITURA!$I$2:$I$1201,1)&" linhas lidas · "&SUMIFS(_LEITURA!$G$2:$G$1201,_LEITURA!$A$2:$A$1201,16,_LEITURA!$I$2:$I$1201,1)&" cartas"&IF(COUNTIFS(_LEITURA!$A$2:$A$1201,16,_LEITURA!$L$2:$L$1201,1)>0," · ATENÇÃO: "&COUNTIFS(_LEITURA!$A$2:$A$1201,16,_LEITURA!$L$2:$L$1201,1)&" linha(s) ignorada(s)","")) | Q3: =IF(COUNTA(Q4:Q63)=0,"",COUNTIFS(_LEITURA!$A$2:$A$1201,17,_LEITURA!$I$2:$I$1201,1)&" linhas lidas · "&SUMIFS(_LEITURA!$G$2:$G$1201,_LEITURA!$A$2:$A$1201,17,_LEITURA!$I$2:$I$1201,1)&" cartas"&IF(COUNTIFS(_LEITURA!$A$2:$A$1201,17,_LEITURA!$L$2:$L$1201,1)>0," · ATENÇÃO: "&COUNTIFS(_LEITURA!$A$2:$A$1201,17,_LEITURA!$L$2:$L$1201,1)&" linha(s) ignorada(s)","")) | R3: =IF(COUNTA(R4:R63)=0,"",COUNTIFS(_LEITURA!$A$2:$A$1201,18,_LEITURA!$I$2:$I$1201,1)&" linhas lidas · "&SUMIFS(_LEITURA!$G$2:$G$1201,_LEITURA!$A$2:$A$1201,18,_LEITURA!$I$2:$I$1201,1)&" cartas"&IF(COUNTIFS(_LEITURA!$A$2:$A$1201,18,_LEITURA!$L$2:$L$1201,1)>0," · ATENÇÃO: "&COUNTIFS(_LEITURA!$A$2:$A$1201,18,_LEITURA!$L$2:$L$1201,1)&" linha(s) ignorada(s)","")) | S3: =IF(COUNTA(S4:S63)=0,"",COUNTIFS(_LEITURA!$A$2:$A$1201,19,_LEITURA!$I$2:$I$1201,1)&" linhas lidas · "&SUMIFS(_LEITURA!$G$2:$G$1201,_LEITURA!$A$2:$A$1201,19,_LEITURA!$I$2:$I$1201,1)&" cartas"&IF(COUNTIFS(_LEITURA!$A$2:$A$1201,19,_LEITURA!$L$2:$L$1201,1)>0," · ATENÇÃO: "&COUNTIFS(_LEITURA!$A$2:$A$1201,19,_LEITURA!$L$2:$L$1201,1)&" linha(s) ignorada(s)","")) | T3: =IF(COUNTA(T4:T63)=0,"",COUNTIFS(_LEITURA!$A$2:$A$1201,20,_LEITURA!$I$2:$I$1201,1)&" linhas lidas · "&SUMIFS(_LEITURA!$G$2:$G$1201,_LEITURA!$A$2:$A$1201,20,_LEITURA!$I$2:$I$1201,1)&" cartas"&IF(COUNTIFS(_LEITURA!$A$2:$A$1201,20,_LEITURA!$L$2:$L$1201,1)>0," · ATENÇÃO: "&COUNTIFS(_LEITURA!$A$2:$A$1201,20,_LEITURA!$L$2:$L$1201,1)&" linha(s) ignorada(s)",""))

Sheet COMPRAS
A1: Data | B1: Código | C1: Quantidade | D1: Nome da carta (automático) | E1: Loja (opcional) | F1: Preço unitário R$ (opcional) | G1: Observação (opcional) | H1: Valor total R$ | I1: Nome manual (opcional) | J1: Aviso | K1: Código usado (aux) | L1: Código com nome digitado (aux) | N1: RESUMO DAS COMPRAS
D2: =IF(K2="","",IFERROR(INDEX(DECKS!$C$2:$C$1201,MATCH(K2,DECKS!$B$2:$B$1201,0)),TRIM(I2&""))) | H2: =IF(OR(N(C2)=0,N(F2)=0),"",C2*F2) | J2: =IF(K2="","",IF(N(C2)<=0,"Informe a quantidade",IF(IFERROR(INDEX(INVENTÁRIO!$B$2:$B$801,MATCH(K2,INVENTÁRIO!$A$2:$A$801,0)),"")="(sem nome)","Carta fora dos decks: digite o nome na coluna I (opcional)",""))) | K2: =UPPER(TRIM(SUBSTITUTE(B2&"",CHAR(160)," "))) | L2: =IF(AND(K2<>"",TRIM(I2&"")<>""),K2,"") | N2: Cartas registradas (total de cópias) | O2: =SUM(C2:C2001) -> 0
D3: =IF(K3="","",IFERROR(INDEX(DECKS!$C$2:$C$1201,MATCH(K3,DECKS!$B$2:$B$1201,0)),TRIM(I3&""))) | H3: =IF(OR(N(C3)=0,N(F3)=0),"",C3*F3) | J3: =IF(K3="","",IF(N(C3)<=0,"Informe a quantidade",IF(IFERROR(INDEX(INVENTÁRIO!$B$2:$B$801,MATCH(K3,INVENTÁRIO!$A$2:$A$801,0)),"")="(sem nome)","Carta fora dos decks: digite o nome na coluna I (opcional)",""))) | K3: =UPPER(TRIM(SUBSTITUTE(B3&"",CHAR(160)," "))) | L3: =IF(AND(K3<>"",TRIM(I3&"")<>""),K3,"") | N3: Gasto registrado (R$) | O3: =SUM(H2:H2001) -> 0
D4: =IF(K4="","",IFERROR(INDEX(DECKS!$C$2:$C$1201,MATCH(K4,DECKS!$B$2:$B$1201,0)),TRIM(I4&""))) | H4: =IF(OR(N(C4)=0,N(F4)=0),"",C4*F4) | J4: =IF(K4="","",IF(N(C4)<=0,"Informe a quantidade",IF(IFERROR(INDEX(INVENTÁRIO!$B$2:$B$801,MATCH(K4,INVENTÁRIO!$A$2:$A$801,0)),"")="(sem nome)","Carta fora dos decks: digite o nome na coluna I (opcional)",""))) | K4: =UPPER(TRIM(SUBSTITUTE(B4&"",CHAR(160)," "))) | L4: =IF(AND(K4<>"",TRIM(I4&"")<>""),K4,"") | N4: Linhas com aviso | O4: =COUNTIF(J2:J2001,"?*") -> 0
D5: =IF(K5="","",IFERROR(INDEX(DECKS!$C$2:$C$1201,MATCH(K5,DECKS!$B$2:$B$1201,0)),TRIM(I5&""))) | H5: =IF(OR(N(C5)=0,N(F5)=0),"",C5*F5) | J5: =IF(K5="","",IF(N(C5)<=0,"Informe a quantidade",IF(IFERROR(INDEX(INVENTÁRIO!$B$2:$B$801,MATCH(K5,INVENTÁRIO!$A$2:$A$801,0)),"")="(sem nome)","Carta fora dos decks: digite o nome na coluna I (opcional)",""))) | K5: =UPPER(TRIM(SUBSTITUTE(B5&"",CHAR(160)," "))) | L5: =IF(AND(K5<>"",TRIM(I5&"")<>""),K5,"")
D6: =IF(K6="","",IFERROR(INDEX(DECKS!$C$2:$C$1201,MATCH(K6,DECKS!$B$2:$B$1201,0)),TRIM(I6&""))) | H6: =IF(OR(N(C6)=0,N(F6)=0),"",C6*F6) | J6: =IF(K6="","",IF(N(C6)<=0,"Informe a quantidade",IF(IFERROR(INDEX(INVENTÁRIO!$B$2:$B$801,MATCH(K6,INVENTÁRIO!$A$2:$A$801,0)),"")="(sem nome)","Carta fora dos decks: digite o nome na coluna I (opcional)",""))) | K6: =UPPER(TRIM(SUBSTITUTE(B6&"",CHAR(160)," "))) | L6: =IF(AND(K6<>"",TRIM(I6&"")<>""),K6,"")
D7: =IF(K7="","",IFERROR(INDEX(DECKS!$C$2:$C$1201,MATCH(K7,DECKS!$B$2:$B$1201,0)),TRIM(I7&""))) | H7: =IF(OR(N(C7)=0,N(F7)=0),"",C7*F7) | J7: =IF(K7="","",IF(N(C7)<=0,"Informe a quantidade",IF(IFERROR(INDEX(INVENTÁRIO!$B$2:$B$801,MATCH(K7,INVENTÁRIO!$A$2:$A$801,0)),"")="(sem nome)","Carta fora dos decks: digite o nome na coluna I (opcional)",""))) | K7: =UPPER(TRIM(SUBSTITUTE(B7&"",CHAR(160)," "))) | L7: =IF(AND(K7<>"",TRIM(I7&"")<>""),K7,"")
D8: =IF(K8="","",IFERROR(INDEX(DECKS!$C$2:$C$1201,MATCH(K8,DECKS!$B$2:$B$1201,0)),TRIM(I8&""))) | H8: =IF(OR(N(C8)=0,N(F8)=0),"",C8*F8) | J8: =IF(K8="","",IF(N(C8)<=0,"Informe a quantidade",IF(IFERROR(INDEX(INVENTÁRIO!$B$2:$B$801,MATCH(K8,INVENTÁRIO!$A$2:$A$801,0)),"")="(sem nome)","Carta fora dos decks: digite o nome na coluna I (opcional)",""))) | K8: =UPPER(TRIM(SUBSTITUTE(B8&"",CHAR(160)," "))) | L8: =IF(AND(K8<>"",TRIM(I8&"")<>""),K8,"")
D9: =IF(K9="","",IFERROR(INDEX(DECKS!$C$2:$C$1201,MATCH(K9,DECKS!$B$2:$B$1201,0)),TRIM(I9&""))) | H9: =IF(OR(N(C9)=0,N(F9)=0),"",C9*F9) | J9: =IF(K9="","",IF(N(C9)<=0,"Informe a quantidade",IF(IFERROR(INDEX(INVENTÁRIO!$B$2:$B$801,MATCH(K9,INVENTÁRIO!$A$2:$A$801,0)),"")="(sem nome)","Carta fora dos decks: digite o nome na coluna I (opcional)",""))) | K9: =UPPER(TRIM(SUBSTITUTE(B9&"",CHAR(160)," "))) | L9: =IF(AND(K9<>"",TRIM(I9&"")<>""),K9,"")
D10: =IF(K10="","",IFERROR(INDEX(DECKS!$C$2:$C$1201,MATCH(K10,DECKS!$B$2:$B$1201,0)),TRIM(I10&""))) | H10: =IF(OR(N(C10)=0,N(F10)=0),"",C10*F10) | J10: =IF(K10="","",IF(N(C10)<=0,"Informe a quantidade",IF(IFERROR(INDEX(INVENTÁRIO!$B$2:$B$801,MATCH(K10,INVENTÁRIO!$A$2:$A$801,0)),"")="(sem nome)","Carta fora dos decks: digite o nome na coluna I (opcional)",""))) | K10: =UPPER(TRIM(SUBSTITUTE(B10&"",CHAR(160)," "))) | L10: =IF(AND(K10<>"",TRIM(I10&"")<>""),K10,"")
D11: =IF(K11="","",IFERROR(INDEX(DECKS!$C$2:$C$1201,MATCH(K11,DECKS!$B$2:$B$1201,0)),TRIM(I11&""))) | H11: =IF(OR(N(C11)=0,N(F11)=0),"",C11*F11) | J11: =IF(K11="","",IF(N(C11)<=0,"Informe a quantidade",IF(IFERROR(INDEX(INVENTÁRIO!$B$2:$B$801,MATCH(K11,INVENTÁRIO!$A$2:$A$801,0)),"")="(sem nome)","Carta fora dos decks: digite o nome na coluna I (opcional)",""))) | K11: =UPPER(TRIM(SUBSTITUTE(B11&"",CHAR(160)," "))) | L11: =IF(AND(K11<>"",TRIM(I11&"")<>""),K11,"")
D12: =IF(K12="","",IFERROR(INDEX(DECKS!$C$2:$C$1201,MATCH(K12,DECKS!$B$2:$B$1201,0)),TRIM(I12&""))) | H12: =IF(OR(N(C12)=0,N(F12)=0),"",C12*F12) | J12: =IF(K12="","",IF(N(C12)<=0,"Informe a quantidade",IF(IFERROR(INDEX(INVENTÁRIO!$B$2:$B$801,MATCH(K12,INVENTÁRIO!$A$2:$A$801,0)),"")="(sem nome)","Carta fora dos decks: digite o nome na coluna I (opcional)",""))) | K12: =UPPER(TRIM(SUBSTITUTE(B12&"",CHAR(160)," "))) | L12: =IF(AND(K12<>"",TRIM(I12&"")<>""),K12,"")
D13: =IF(K13="","",IFERROR(INDEX(DECKS!$C$2:$C$1201,MATCH(K13,DECKS!$B$2:$B$1201,0)),TRIM(I13&""))) | H13: =IF(OR(N(C13)=0,N(F13)=0),"",C13*F13) | J13: =IF(K13="","",IF(N(C13)<=0,"Informe a quantidade",IF(IFERROR(INDEX(INVENTÁRIO!$B$2:$B$801,MATCH(K13,INVENTÁRIO!$A$2:$A$801,0)),"")="(sem nome)","Carta fora dos decks: digite o nome na coluna I (opcional)",""))) | K13: =UPPER(TRIM(SUBSTITUTE(B13&"",CHAR(160)," "))) | L13: =IF(AND(K13<>"",TRIM(I13&"")<>""),K13,"")
D14: =IF(K14="","",IFERROR(INDEX(DECKS!$C$2:$C$1201,MATCH(K14,DECKS!$B$2:$B$1201,0)),TRIM(I14&""))) | H14: =IF(OR(N(C14)=0,N(F14)=0),"",C14*F14) | J14: =IF(K14="","",IF(N(C14)<=0,"Informe a quantidade",IF(IFERROR(INDEX(INVENTÁRIO!$B$2:$B$801,MATCH(K14,INVENTÁRIO!$A$2:$A$801,0)),"")="(sem nome)","Carta fora dos decks: digite o nome na coluna I (opcional)",""))) | K14: =UPPER(TRIM(SUBSTITUTE(B14&"",CHAR(160)," "))) | L14: =IF(AND(K14<>"",TRIM(I14&"")<>""),K14,"")
D15: =IF(K15="","",IFERROR(INDEX(DECKS!$C$2:$C$1201,MATCH(K15,DECKS!$B$2:$B$1201,0)),TRIM(I15&""))) | H15: =IF(OR(N(C15)=0,N(F15)=0),"",C15*F15) | J15: =IF(K15="","",IF(N(C15)<=0,"Informe a quantidade",IF(IFERROR(INDEX(INVENTÁRIO!$B$2:$B$801,MATCH(K15,INVENTÁRIO!$A$2:$A$801,0)),"")="(sem nome)","Carta fora dos decks: digite o nome na coluna I (opcional)",""))) | K15: =UPPER(TRIM(SUBSTITUTE(B15&"",CHAR(160)," "))) | L15: =IF(AND(K15<>"",TRIM(I15&"")<>""),K15,"")
D16: =IF(K16="","",IFERROR(INDEX(DECKS!$C$2:$C$1201,MATCH(K16,DECKS!$B$2:$B$1201,0)),TRIM(I16&""))) | H16: =IF(OR(N(C16)=0,N(F16)=0),"",C16*F16) | J16: =IF(K16="","",IF(N(C16)<=0,"Informe a quantidade",IF(IFERROR(INDEX(INVENTÁRIO!$B$2:$B$801,MATCH(K16,INVENTÁRIO!$A$2:$A$801,0)),"")="(sem nome)","Carta fora dos decks: digite o nome na coluna I (opcional)",""))) | K16: =UPPER(TRIM(SUBSTITUTE(B16&"",CHAR(160)," "))) | L16: =IF(AND(K16<>"",TRIM(I16&"")<>""),K16,"")
... D2001: =IF(K2001="","",IFERROR(INDEX(DECKS!$C$2:$C$1201,MATCH(K2001,DECKS!$B$2:$B$1201,0)),TRIM(I2001&""))) | H2001: =IF(OR(N(C2001)=0,N(F2001)=0),"",C2001*F2001) | J2001: =IF(K2001="","",IF(N(C2001)<=0,"Informe a quantidade",IF(IFERROR(INDEX(INVENTÁRIO!$B$2:$B$801,MATCH(K2001,INVENTÁRIO!$A$2:$A$801,0)),"")="(sem nome)","Carta fora dos decks: digite o nome na coluna I (opcional)",""))) | K2001: =UPPER(TRIM(SUBSTITUTE(B2001&"",CHAR(160)," "))) | L2001: =IF(AND(K2001<>"",TRIM(I2001&"")<>""),K2001,"")

Sheet INVENTÁRIO
A1: Código | B1: Nome | C1: Tenho | E1: Esta aba é calculada: o Tenho é a soma das COMPRAS. Para mudar, registre uma compra na aba COMPRAS.
A2: =IFERROR(INDEX(_AUX!$A$2:$A$3201,MATCH(ROW()-1,_AUX!$C$2:$C$3201,0)),"") | B2: =IF(A2="","",IFERROR(INDEX(DECKS!$C$2:$C$1201,MATCH(A2,DECKS!$B$2:$B$1201,0)),IFERROR(TRIM(INDEX(COMPRAS!$I$2:$I$2001,MATCH(A2,COMPRAS!$L$2:$L$2001,0))),"(sem nome)"))) | C2: =IF(A2="","",SUMIFS(COMPRAS!$C$2:$C$2001,COMPRAS!$K$2:$K$2001,A2))
A3: =IFERROR(INDEX(_AUX!$A$2:$A$3201,MATCH(ROW()-1,_AUX!$C$2:$C$3201,0)),"") | B3: =IF(A3="","",IFERROR(INDEX(DECKS!$C$2:$C$1201,MATCH(A3,DECKS!$B$2:$B$1201,0)),IFERROR(TRIM(INDEX(COMPRAS!$I$2:$I$2001,MATCH(A3,COMPRAS!$L$2:$L$2001,0))),"(sem nome)"))) | C3: =IF(A3="","",SUMIFS(COMPRAS!$C$2:$C$2001,COMPRAS!$K$2:$K$2001,A3))
A4: =IFERROR(INDEX(_AUX!$A$2:$A$3201,MATCH(ROW()-1,_AUX!$C$2:$C$3201,0)),"") | B4: =IF(A4="","",IFERROR(INDEX(DECKS!$C$2:$C$1201,MATCH(A4,DECKS!$B$2:$B$1201,0)),IFERROR(TRIM(INDEX(COMPRAS!$I$2:$I$2001,MATCH(A4,COMPRAS!$L$2:$L$2001,0))),"(sem nome)"))) | C4: =IF(A4="","",SUMIFS(COMPRAS!$C$2:$C$2001,COMPRAS!$K$2:$K$2001,A4))
A5: =IFERROR(INDEX(_AUX!$A$2:$A$3201,MATCH(ROW()-1,_AUX!$C$2:$C$3201,0)),"") | B5: =IF(A5="","",IFERROR(INDEX(DECKS!$C$2:$C$1201,MATCH(A5,DECKS!$B$2:$B$1201,0)),IFERROR(TRIM(INDEX(COMPRAS!$I$2:$I$2001,MATCH(A5,COMPRAS!$L$2:$L$2001,0))),"(sem nome)"))) | C5: =IF(A5="","",SUMIFS(COMPRAS!$C$2:$C$2001,COMPRAS!$K$2:$K$2001,A5))
A6: =IFERROR(INDEX(_AUX!$A$2:$A$3201,MATCH(ROW()-1,_AUX!$C$2:$C$3201,0)),"") | B6: =IF(A6="","",IFERROR(INDEX(DECKS!$C$2:$C$1201,MATCH(A6,DECKS!$B$2:$B$1201,0)),IFERROR(TRIM(INDEX(COMPRAS!$I$2:$I$2001,MATCH(A6,COMPRAS!$L$2:$L$2001,0))),"(sem nome)"))) | C6: =IF(A6="","",SUMIFS(COMPRAS!$C$2:$C$2001,COMPRAS!$K$2:$K$2001,A6))
A7: =IFERROR(INDEX(_AUX!$A$2:$A$3201,MATCH(ROW()-1,_AUX!$C$2:$C$3201,0)),"") | B7: =IF(A7="","",IFERROR(INDEX(DECKS!$C$2:$C$1201,MATCH(A7,DECKS!$B$2:$B$1201,0)),IFERROR(TRIM(INDEX(COMPRAS!$I$2:$I$2001,MATCH(A7,COMPRAS!$L$2:$L$2001,0))),"(sem nome)"))) | C7: =IF(A7="","",SUMIFS(COMPRAS!$C$2:$C$2001,COMPRAS!$K$2:$K$2001,A7))
A8: =IFERROR(INDEX(_AUX!$A$2:$A$3201,MATCH(ROW()-1,_AUX!$C$2:$C$3201,0)),"") | B8: =IF(A8="","",IFERROR(INDEX(DECKS!$C$2:$C$1201,MATCH(A8,DECKS!$B$2:$B$1201,0)),IFERROR(TRIM(INDEX(COMPRAS!$I$2:$I$2001,MATCH(A8,COMPRAS!$L$2:$L$2001,0))),"(sem nome)"))) | C8: =IF(A8="","",SUMIFS(COMPRAS!$C$2:$C$2001,COMPRAS!$K$2:$K$2001,A8))
A9: =IFERROR(INDEX(_AUX!$A$2:$A$3201,MATCH(ROW()-1,_AUX!$C$2:$C$3201,0)),"") | B9: =IF(A9="","",IFERROR(INDEX(DECKS!$C$2:$C$1201,MATCH(A9,DECKS!$B$2:$B$1201,0)),IFERROR(TRIM(INDEX(COMPRAS!$I$2:$I$2001,MATCH(A9,COMPRAS!$L$2:$L$2001,0))),"(sem nome)"))) | C9: =IF(A9="","",SUMIFS(COMPRAS!$C$2:$C$2001,COMPRAS!$K$2:$K$2001,A9))
A10: =IFERROR(INDEX(_AUX!$A$2:$A$3201,MATCH(ROW()-1,_AUX!$C$2:$C$3201,0)),"") | B10: =IF(A10="","",IFERROR(INDEX(DECKS!$C$2:$C$1201,MATCH(A10,DECKS!$B$2:$B$1201,0)),IFERROR(TRIM(INDEX(COMPRAS!$I$2:$I$2001,MATCH(A10,COMPRAS!$L$2:$L$2001,0))),"(sem nome)"))) | C10: =IF(A10="","",SUMIFS(COMPRAS!$C$2:$C$2001,COMPRAS!$K$2:$K$2001,A10))
A11: =IFERROR(INDEX(_AUX!$A$2:$A$3201,MATCH(ROW()-1,_AUX!$C$2:$C$3201,0)),"") | B11: =IF(A11="","",IFERROR(INDEX(DECKS!$C$2:$C$1201,MATCH(A11,DECKS!$B$2:$B$1201,0)),IFERROR(TRIM(INDEX(COMPRAS!$I$2:$I$2001,MATCH(A11,COMPRAS!$L$2:$L$2001,0))),"(sem nome)"))) | C11: =IF(A11="","",SUMIFS(COMPRAS!$C$2:$C$2001,COMPRAS!$K$2:$K$2001,A11))
A12: =IFERROR(INDEX(_AUX!$A$2:$A$3201,MATCH(ROW()-1,_AUX!$C$2:$C$3201,0)),"") | B12: =IF(A12="","",IFERROR(INDEX(DECKS!$C$2:$C$1201,MATCH(A12,DECKS!$B$2:$B$1201,0)),IFERROR(TRIM(INDEX(COMPRAS!$I$2:$I$2001,MATCH(A12,COMPRAS!$L$2:$L$2001,0))),"(sem nome)"))) | C12: =IF(A12="","",SUMIFS(COMPRAS!$C$2:$C$2001,COMPRAS!$K$2:$K$2001,A12))
A13: =IFERROR(INDEX(_AUX!$A$2:$A$3201,MATCH(ROW()-1,_AUX!$C$2:$C$3201,0)),"") | B13: =IF(A13="","",IFERROR(INDEX(DECKS!$C$2:$C$1201,MATCH(A13,DECKS!$B$2:$B$1201,0)),IFERROR(TRIM(INDEX(COMPRAS!$I$2:$I$2001,MATCH(A13,COMPRAS!$L$2:$L$2001,0))),"(sem nome)"))) | C13: =IF(A13="","",SUMIFS(COMPRAS!$C$2:$C$2001,COMPRAS!$K$2:$K$2001,A13))
... A801: =IFERROR(INDEX(_AUX!$A$2:$A$3201,MATCH(ROW()-1,_AUX!$C$2:$C$3201,0)),"") | B801: =IF(A801="","",IFERROR(INDEX(DECKS!$C$2:$C$1201,MATCH(A801,DECKS!$B$2:$B$1201,0)),IFERROR(TRIM(INDEX(COMPRAS!$I$2:$I$2001,MATCH(A801,COMPRAS!$L$2:$L$2001,0))),"(sem nome)"))) | C801: =IF(A801="","",SUMIFS(COMPRAS!$C$2:$C$2001,COMPRAS!$K$2:$K$2001,A801))

Sheet DECKS
A1: Deck | B1: Código | C1: Nome | D1: Quantidade necessária | E1: Tenho (global) | F1: Falta para o deck | G1: Compartilhada? | H1: Seq. falta (aux) | I1: Alerta | J1: Seq. deck da aba BULK (aux) | K1: Antes do hífen (aux) | L1: Nº de letras (aux) | M1: Chave do código (aux) | N1: Chave de ordenação (aux) | O1: Posição na ordenação (aux) | Q1: Aba calculada a partir da aba LISTAS. Não edite aqui.
A2: =IF(_LEITURA!$N2="","",INDEX(_LEITURA!$K$2:$K$1201,_LEITURA!$N2)) | B2: =IF(_LEITURA!$N2="","",INDEX(_LEITURA!$E$2:$E$1201,_LEITURA!$N2)) | C2: =IF(_LEITURA!$N2="","",INDEX(_LEITURA!$J$2:$J$1201,_LEITURA!$N2)) | D2: =IF(_LEITURA!$N2="","",INDEX(_LEITURA!$G$2:$G$1201,_LEITURA!$N2)) | E2: =IF(B2="","",SUMIFS(INVENTÁRIO!$C$2:$C$801,INVENTÁRIO!$A$2:$A$801,B2)) | F2: =IF(B2="","",MAX(0,D2-E2)) | G2: =IF(B2="","",IF(COUNTIFS($B$2:$B$1201,B2,$A$2:$A$1201,"<>"&A2)>0,"Sim","")) | H2: =IF(N(F2)>0,MAX(H$1:H1)+1,"") | I2: =IF(B2="","",IF(INDEX($C$2:$C$1201,MATCH(B2,$B$2:$B$1201,0))<>C2,"Nome diferente em outro deck — revisar","")) | J2: =IF(AND(B2<>"",A2=BULK!$A$1,N(F2)>0),MAX(J$1:J1)+1,"") | K2: =IF(B2="","",IFERROR(LEFT(B2,FIND("-",B2)-1),B2)) | L2: =IF(K2="","",IF(ISNUMBER(--MID(K2,1,1)),0,IF(ISNUMBER(--MID(K2,2,1)),1,IF(ISNUMBER(--MID(K2,3,1)),2,IF(ISNUMBER(--MID(K2,4,1)),3,MIN(LEN(K2),4)))))) | M2: =IF(B2="","",LEFT(K2,L2)&REPT("0",4-L2)&RIGHT("000"&IFERROR(VALUE(MID(K2,L2+1,9)),0),3)&RIGHT("0000"&IFERROR(VALUE(MID(B2,FIND("-",B2)+1,9)),0),4)) | N2: =IF(OR(B2="",N(F2)<=0),"",IF('FALTAS POR DECK'!$P$1="Código","K"&M2&RIGHT("00000"&ROW(),5),IF('FALTAS POR DECK'!$P$1="Nome","K"&UPPER(SUBSTITUTE(SUBSTITUTE(SUBSTITUTE(C2,"*",""),"?",""),"~",""))&"0"&M2&RIGHT("00000"&ROW(),5),IF('FALTAS POR DECK'!$P$1="Falta (maior primeiro)","K"&RIGHT("0000"&(9999-F2),4)&M2&RIGHT("00000"&ROW(),5),IF('FALTAS POR DECK'!$P$1="Deck e código","K"&RIGHT("00"&IFERROR(MATCH(A2,_LEITURA!$P$2:$P$21,0),99),2)&M2&RIGHT("00000"&ROW(),5),"K"&RIGHT("00000"&ROW(),5)))))) | O2: =IF(N2="","",COUNTIFS($N$2:$N$1201,"<"&N2,$F$2:$F$1201,">0")+1)
A3: =IF(_LEITURA!$N3="","",INDEX(_LEITURA!$K$2:$K$1201,_LEITURA!$N3)) | B3: =IF(_LEITURA!$N3="","",INDEX(_LEITURA!$E$2:$E$1201,_LEITURA!$N3)) | C3: =IF(_LEITURA!$N3="","",INDEX(_LEITURA!$J$2:$J$1201,_LEITURA!$N3)) | D3: =IF(_LEITURA!$N3="","",INDEX(_LEITURA!$G$2:$G$1201,_LEITURA!$N3)) | E3: =IF(B3="","",SUMIFS(INVENTÁRIO!$C$2:$C$801,INVENTÁRIO!$A$2:$A$801,B3)) | F3: =IF(B3="","",MAX(0,D3-E3)) | G3: =IF(B3="","",IF(COUNTIFS($B$2:$B$1201,B3,$A$2:$A$1201,"<>"&A3)>0,"Sim","")) | H3: =IF(N(F3)>0,MAX(H$1:H2)+1,"") | I3: =IF(B3="","",IF(INDEX($C$2:$C$1201,MATCH(B3,$B$2:$B$1201,0))<>C3,"Nome diferente em outro deck — revisar","")) | J3: =IF(AND(B3<>"",A3=BULK!$A$1,N(F3)>0),MAX(J$1:J2)+1,"") | K3: =IF(B3="","",IFERROR(LEFT(B3,FIND("-",B3)-1),B3)) | L3: =IF(K3="","",IF(ISNUMBER(--MID(K3,1,1)),0,IF(ISNUMBER(--MID(K3,2,1)),1,IF(ISNUMBER(--MID(K3,3,1)),2,IF(ISNUMBER(--MID(K3,4,1)),3,MIN(LEN(K3),4)))))) | M3: =IF(B3="","",LEFT(K3,L3)&REPT("0",4-L3)&RIGHT("000"&IFERROR(VALUE(MID(K3,L3+1,9)),0),3)&RIGHT("0000"&IFERROR(VALUE(MID(B3,FIND("-",B3)+1,9)),0),4)) | N3: =IF(OR(B3="",N(F3)<=0),"",IF('FALTAS POR DECK'!$P$1="Código","K"&M3&RIGHT("00000"&ROW(),5),IF('FALTAS POR DECK'!$P$1="Nome","K"&UPPER(SUBSTITUTE(SUBSTITUTE(SUBSTITUTE(C3,"*",""),"?",""),"~",""))&"0"&M3&RIGHT("00000"&ROW(),5),IF('FALTAS POR DECK'!$P$1="Falta (maior primeiro)","K"&RIGHT("0000"&(9999-F3),4)&M3&RIGHT("00000"&ROW(),5),IF('FALTAS POR DECK'!$P$1="Deck e código","K"&RIGHT("00"&IFERROR(MATCH(A3,_LEITURA!$P$2:$P$21,0),99),2)&M3&RIGHT("00000"&ROW(),5),"K"&RIGHT("00000"&ROW(),5)))))) | O3: =IF(N3="","",COUNTIFS($N$2:$N$1201,"<"&N3,$F$2:$F$1201,">0")+1)
A4: =IF(_LEITURA!$N4="","",INDEX(_LEITURA!$K$2:$K$1201,_LEITURA!$N4)) | B4: =IF(_LEITURA!$N4="","",INDEX(_LEITURA!$E$2:$E$1201,_LEITURA!$N4)) | C4: =IF(_LEITURA!$N4="","",INDEX(_LEITURA!$J$2:$J$1201,_LEITURA!$N4)) | D4: =IF(_LEITURA!$N4="","",INDEX(_LEITURA!$G$2:$G$1201,_LEITURA!$N4)) | E4: =IF(B4="","",SUMIFS(INVENTÁRIO!$C$2:$C$801,INVENTÁRIO!$A$2:$A$801,B4)) | F4: =IF(B4="","",MAX(0,D4-E4)) | G4: =IF(B4="","",IF(COUNTIFS($B$2:$B$1201,B4,$A$2:$A$1201,"<>"&A4)>0,"Sim","")) | H4: =IF(N(F4)>0,MAX(H$1:H3)+1,"") | I4: =IF(B4="","",IF(INDEX($C$2:$C$1201,MATCH(B4,$B$2:$B$1201,0))<>C4,"Nome diferente em outro deck — revisar","")) | J4: =IF(AND(B4<>"",A4=BULK!$A$1,N(F4)>0),MAX(J$1:J3)+1,"") | K4: =IF(B4="","",IFERROR(LEFT(B4,FIND("-",B4)-1),B4)) | L4: =IF(K4="","",IF(ISNUMBER(--MID(K4,1,1)),0,IF(ISNUMBER(--MID(K4,2,1)),1,IF(ISNUMBER(--MID(K4,3,1)),2,IF(ISNUMBER(--MID(K4,4,1)),3,MIN(LEN(K4),4)))))) | M4: =IF(B4="","",LEFT(K4,L4)&REPT("0",4-L4)&RIGHT("000"&IFERROR(VALUE(MID(K4,L4+1,9)),0),3)&RIGHT("0000"&IFERROR(VALUE(MID(B4,FIND("-",B4)+1,9)),0),4)) | N4: =IF(OR(B4="",N(F4)<=0),"",IF('FALTAS POR DECK'!$P$1="Código","K"&M4&RIGHT("00000"&ROW(),5),IF('FALTAS POR DECK'!$P$1="Nome","K"&UPPER(SUBSTITUTE(SUBSTITUTE(SUBSTITUTE(C4,"*",""),"?",""),"~",""))&"0"&M4&RIGHT("00000"&ROW(),5),IF('FALTAS POR DECK'!$P$1="Falta (maior primeiro)","K"&RIGHT("0000"&(9999-F4),4)&M4&RIGHT("00000"&ROW(),5),IF('FALTAS POR DECK'!$P$1="Deck e código","K"&RIGHT("00"&IFERROR(MATCH(A4,_LEITURA!$P$2:$P$21,0),99),2)&M4&RIGHT("00000"&ROW(),5),"K"&RIGHT("00000"&ROW(),5)))))) | O4: =IF(N4="","",COUNTIFS($N$2:$N$1201,"<"&N4,$F$2:$F$1201,">0")+1)
A5: =IF(_LEITURA!$N5="","",INDEX(_LEITURA!$K$2:$K$1201,_LEITURA!$N5)) | B5: =IF(_LEITURA!$N5="","",INDEX(_LEITURA!$E$2:$E$1201,_LEITURA!$N5)) | C5: =IF(_LEITURA!$N5="","",INDEX(_LEITURA!$J$2:$J$1201,_LEITURA!$N5)) | D5: =IF(_LEITURA!$N5="","",INDEX(_LEITURA!$G$2:$G$1201,_LEITURA!$N5)) | E5: =IF(B5="","",SUMIFS(INVENTÁRIO!$C$2:$C$801,INVENTÁRIO!$A$2:$A$801,B5)) | F5: =IF(B5="","",MAX(0,D5-E5)) | G5: =IF(B5="","",IF(COUNTIFS($B$2:$B$1201,B5,$A$2:$A$1201,"<>"&A5)>0,"Sim","")) | H5: =IF(N(F5)>0,MAX(H$1:H4)+1,"") | I5: =IF(B5="","",IF(INDEX($C$2:$C$1201,MATCH(B5,$B$2:$B$1201,0))<>C5,"Nome diferente em outro deck — revisar","")) | J5: =IF(AND(B5<>"",A5=BULK!$A$1,N(F5)>0),MAX(J$1:J4)+1,"") | K5: =IF(B5="","",IFERROR(LEFT(B5,FIND("-",B5)-1),B5)) | L5: =IF(K5="","",IF(ISNUMBER(--MID(K5,1,1)),0,IF(ISNUMBER(--MID(K5,2,1)),1,IF(ISNUMBER(--MID(K5,3,1)),2,IF(ISNUMBER(--MID(K5,4,1)),3,MIN(LEN(K5),4)))))) | M5: =IF(B5="","",LEFT(K5,L5)&REPT("0",4-L5)&RIGHT("000"&IFERROR(VALUE(MID(K5,L5+1,9)),0),3)&RIGHT("0000"&IFERROR(VALUE(MID(B5,FIND("-",B5)+1,9)),0),4)) | N5: =IF(OR(B5="",N(F5)<=0),"",IF('FALTAS POR DECK'!$P$1="Código","K"&M5&RIGHT("00000"&ROW(),5),IF('FALTAS POR DECK'!$P$1="Nome","K"&UPPER(SUBSTITUTE(SUBSTITUTE(SUBSTITUTE(C5,"*",""),"?",""),"~",""))&"0"&M5&RIGHT("00000"&ROW(),5),IF('FALTAS POR DECK'!$P$1="Falta (maior primeiro)","K"&RIGHT("0000"&(9999-F5),4)&M5&RIGHT("00000"&ROW(),5),IF('FALTAS POR DECK'!$P$1="Deck e código","K"&RIGHT("00"&IFERROR(MATCH(A5,_LEITURA!$P$2:$P$21,0),99),2)&M5&RIGHT("00000"&ROW(),5),"K"&RIGHT("00000"&ROW(),5)))))) | O5: =IF(N5="","",COUNTIFS($N$2:$N$1201,"<"&N5,$F$2:$F$1201,">0")+1)
A6: =IF(_LEITURA!$N6="","",INDEX(_LEITURA!$K$2:$K$1201,_LEITURA!$N6)) | B6: =IF(_LEITURA!$N6="","",INDEX(_LEITURA!$E$2:$E$1201,_LEITURA!$N6)) | C6: =IF(_LEITURA!$N6="","",INDEX(_LEITURA!$J$2:$J$1201,_LEITURA!$N6)) | D6: =IF(_LEITURA!$N6="","",INDEX(_LEITURA!$G$2:$G$1201,_LEITURA!$N6)) | E6: =IF(B6="","",SUMIFS(INVENTÁRIO!$C$2:$C$801,INVENTÁRIO!$A$2:$A$801,B6)) | F6: =IF(B6="","",MAX(0,D6-E6)) | G6: =IF(B6="","",IF(COUNTIFS($B$2:$B$1201,B6,$A$2:$A$1201,"<>"&A6)>0,"Sim","")) | H6: =IF(N(F6)>0,MAX(H$1:H5)+1,"") | I6: =IF(B6="","",IF(INDEX($C$2:$C$1201,MATCH(B6,$B$2:$B$1201,0))<>C6,"Nome diferente em outro deck — revisar","")) | J6: =IF(AND(B6<>"",A6=BULK!$A$1,N(F6)>0),MAX(J$1:J5)+1,"") | K6: =IF(B6="","",IFERROR(LEFT(B6,FIND("-",B6)-1),B6)) | L6: =IF(K6="","",IF(ISNUMBER(--MID(K6,1,1)),0,IF(ISNUMBER(--MID(K6,2,1)),1,IF(ISNUMBER(--MID(K6,3,1)),2,IF(ISNUMBER(--MID(K6,4,1)),3,MIN(LEN(K6),4)))))) | M6: =IF(B6="","",LEFT(K6,L6)&REPT("0",4-L6)&RIGHT("000"&IFERROR(VALUE(MID(K6,L6+1,9)),0),3)&RIGHT("0000"&IFERROR(VALUE(MID(B6,FIND("-",B6)+1,9)),0),4)) | N6: =IF(OR(B6="",N(F6)<=0),"",IF('FALTAS POR DECK'!$P$1="Código","K"&M6&RIGHT("00000"&ROW(),5),IF('FALTAS POR DECK'!$P$1="Nome","K"&UPPER(SUBSTITUTE(SUBSTITUTE(SUBSTITUTE(C6,"*",""),"?",""),"~",""))&"0"&M6&RIGHT("00000"&ROW(),5),IF('FALTAS POR DECK'!$P$1="Falta (maior primeiro)","K"&RIGHT("0000"&(9999-F6),4)&M6&RIGHT("00000"&ROW(),5),IF('FALTAS POR DECK'!$P$1="Deck e código","K"&RIGHT("00"&IFERROR(MATCH(A6,_LEITURA!$P$2:$P$21,0),99),2)&M6&RIGHT("00000"&ROW(),5),"K"&RIGHT("00000"&ROW(),5)))))) | O6: =IF(N6="","",COUNTIFS($N$2:$N$1201,"<"&N6,$F$2:$F$1201,">0")+1)
A7: =IF(_LEITURA!$N7="","",INDEX(_LEITURA!$K$2:$K$1201,_LEITURA!$N7)) | B7: =IF(_LEITURA!$N7="","",INDEX(_LEITURA!$E$2:$E$1201,_LEITURA!$N7)) | C7: =IF(_LEITURA!$N7="","",INDEX(_LEITURA!$J$2:$J$1201,_LEITURA!$N7)) | D7: =IF(_LEITURA!$N7="","",INDEX(_LEITURA!$G$2:$G$1201,_LEITURA!$N7)) | E7: =IF(B7="","",SUMIFS(INVENTÁRIO!$C$2:$C$801,INVENTÁRIO!$A$2:$A$801,B7)) | F7: =IF(B7="","",MAX(0,D7-E7)) | G7: =IF(B7="","",IF(COUNTIFS($B$2:$B$1201,B7,$A$2:$A$1201,"<>"&A7)>0,"Sim","")) | H7: =IF(N(F7)>0,MAX(H$1:H6)+1,"") | I7: =IF(B7="","",IF(INDEX($C$2:$C$1201,MATCH(B7,$B$2:$B$1201,0))<>C7,"Nome diferente em outro deck — revisar","")) | J7: =IF(AND(B7<>"",A7=BULK!$A$1,N(F7)>0),MAX(J$1:J6)+1,"") | K7: =IF(B7="","",IFERROR(LEFT(B7,FIND("-",B7)-1),B7)) | L7: =IF(K7="","",IF(ISNUMBER(--MID(K7,1,1)),0,IF(ISNUMBER(--MID(K7,2,1)),1,IF(ISNUMBER(--MID(K7,3,1)),2,IF(ISNUMBER(--MID(K7,4,1)),3,MIN(LEN(K7),4)))))) | M7: =IF(B7="","",LEFT(K7,L7)&REPT("0",4-L7)&RIGHT("000"&IFERROR(VALUE(MID(K7,L7+1,9)),0),3)&RIGHT("0000"&IFERROR(VALUE(MID(B7,FIND("-",B7)+1,9)),0),4)) | N7: =IF(OR(B7="",N(F7)<=0),"",IF('FALTAS POR DECK'!$P$1="Código","K"&M7&RIGHT("00000"&ROW(),5),IF('FALTAS POR DECK'!$P$1="Nome","K"&UPPER(SUBSTITUTE(SUBSTITUTE(SUBSTITUTE(C7,"*",""),"?",""),"~",""))&"0"&M7&RIGHT("00000"&ROW(),5),IF('FALTAS POR DECK'!$P$1="Falta (maior primeiro)","K"&RIGHT("0000"&(9999-F7),4)&M7&RIGHT("00000"&ROW(),5),IF('FALTAS POR DECK'!$P$1="Deck e código","K"&RIGHT("00"&IFERROR(MATCH(A7,_LEITURA!$P$2:$P$21,0),99),2)&M7&RIGHT("00000"&ROW(),5),"K"&RIGHT("00000"&ROW(),5)))))) | O7: =IF(N7="","",COUNTIFS($N$2:$N$1201,"<"&N7,$F$2:$F$1201,">0")+1)
A8: =IF(_LEITURA!$N8="","",INDEX(_LEITURA!$K$2:$K$1201,_LEITURA!$N8)) | B8: =IF(_LEITURA!$N8="","",INDEX(_LEITURA!$E$2:$E$1201,_LEITURA!$N8)) | C8: =IF(_LEITURA!$N8="","",INDEX(_LEITURA!$J$2:$J$1201,_LEITURA!$N8)) | D8: =IF(_LEITURA!$N8="","",INDEX(_LEITURA!$G$2:$G$1201,_LEITURA!$N8)) | E8: =IF(B8="","",SUMIFS(INVENTÁRIO!$C$2:$C$801,INVENTÁRIO!$A$2:$A$801,B8)) | F8: =IF(B8="","",MAX(0,D8-E8)) | G8: =IF(B8="","",IF(COUNTIFS($B$2:$B$1201,B8,$A$2:$A$1201,"<>"&A8)>0,"Sim","")) | H8: =IF(N(F8)>0,MAX(H$1:H7)+1,"") | I8: =IF(B8="","",IF(INDEX($C$2:$C$1201,MATCH(B8,$B$2:$B$1201,0))<>C8,"Nome diferente em outro deck — revisar","")) | J8: =IF(AND(B8<>"",A8=BULK!$A$1,N(F8)>0),MAX(J$1:J7)+1,"") | K8: =IF(B8="","",IFERROR(LEFT(B8,FIND("-",B8)-1),B8)) | L8: =IF(K8="","",IF(ISNUMBER(--MID(K8,1,1)),0,IF(ISNUMBER(--MID(K8,2,1)),1,IF(ISNUMBER(--MID(K8,3,1)),2,IF(ISNUMBER(--MID(K8,4,1)),3,MIN(LEN(K8),4)))))) | M8: =IF(B8="","",LEFT(K8,L8)&REPT("0",4-L8)&RIGHT("000"&IFERROR(VALUE(MID(K8,L8+1,9)),0),3)&RIGHT("0000"&IFERROR(VALUE(MID(B8,FIND("-",B8)+1,9)),0),4)) | N8: =IF(OR(B8="",N(F8)<=0),"",IF('FALTAS POR DECK'!$P$1="Código","K"&M8&RIGHT("00000"&ROW(),5),IF('FALTAS POR DECK'!$P$1="Nome","K"&UPPER(SUBSTITUTE(SUBSTITUTE(SUBSTITUTE(C8,"*",""),"?",""),"~",""))&"0"&M8&RIGHT("00000"&ROW(),5),IF('FALTAS POR DECK'!$P$1="Falta (maior primeiro)","K"&RIGHT("0000"&(9999-F8),4)&M8&RIGHT("00000"&ROW(),5),IF('FALTAS POR DECK'!$P$1="Deck e código","K"&RIGHT("00"&IFERROR(MATCH(A8,_LEITURA!$P$2:$P$21,0),99),2)&M8&RIGHT("00000"&ROW(),5),"K"&RIGHT("00000"&ROW(),5)))))) | O8: =IF(N8="","",COUNTIFS($N$2:$N$1201,"<"&N8,$F$2:$F$1201,">0")+1)
A9: =IF(_LEITURA!$N9="","",INDEX(_LEITURA!$K$2:$K$1201,_LEITURA!$N9)) | B9: =IF(_LEITURA!$N9="","",INDEX(_LEITURA!$E$2:$E$1201,_LEITURA!$N9)) | C9: =IF(_LEITURA!$N9="","",INDEX(_LEITURA!$J$2:$J$1201,_LEITURA!$N9)) | D9: =IF(_LEITURA!$N9="","",INDEX(_LEITURA!$G$2:$G$1201,_LEITURA!$N9)) | E9: =IF(B9="","",SUMIFS(INVENTÁRIO!$C$2:$C$801,INVENTÁRIO!$A$2:$A$801,B9)) | F9: =IF(B9="","",MAX(0,D9-E9)) | G9: =IF(B9="","",IF(COUNTIFS($B$2:$B$1201,B9,$A$2:$A$1201,"<>"&A9)>0,"Sim","")) | H9: =IF(N(F9)>0,MAX(H$1:H8)+1,"") | I9: =IF(B9="","",IF(INDEX($C$2:$C$1201,MATCH(B9,$B$2:$B$1201,0))<>C9,"Nome diferente em outro deck — revisar","")) | J9: =IF(AND(B9<>"",A9=BULK!$A$1,N(F9)>0),MAX(J$1:J8)+1,"") | K9: =IF(B9="","",IFERROR(LEFT(B9,FIND("-",B9)-1),B9)) | L9: =IF(K9="","",IF(ISNUMBER(--MID(K9,1,1)),0,IF(ISNUMBER(--MID(K9,2,1)),1,IF(ISNUMBER(--MID(K9,3,1)),2,IF(ISNUMBER(--MID(K9,4,1)),3,MIN(LEN(K9),4)))))) | M9: =IF(B9="","",LEFT(K9,L9)&REPT("0",4-L9)&RIGHT("000"&IFERROR(VALUE(MID(K9,L9+1,9)),0),3)&RIGHT("0000"&IFERROR(VALUE(MID(B9,FIND("-",B9)+1,9)),0),4)) | N9: =IF(OR(B9="",N(F9)<=0),"",IF('FALTAS POR DECK'!$P$1="Código","K"&M9&RIGHT("00000"&ROW(),5),IF('FALTAS POR DECK'!$P$1="Nome","K"&UPPER(SUBSTITUTE(SUBSTITUTE(SUBSTITUTE(C9,"*",""),"?",""),"~",""))&"0"&M9&RIGHT("00000"&ROW(),5),IF('FALTAS POR DECK'!$P$1="Falta (maior primeiro)","K"&RIGHT("0000"&(9999-F9),4)&M9&RIGHT("00000"&ROW(),5),IF('FALTAS POR DECK'!$P$1="Deck e código","K"&RIGHT("00"&IFERROR(MATCH(A9,_LEITURA!$P$2:$P$21,0),99),2)&M9&RIGHT("00000"&ROW(),5),"K"&RIGHT("00000"&ROW(),5)))))) | O9: =IF(N9="","",COUNTIFS($N$2:$N$1201,"<"&N9,$F$2:$F$1201,">0")+1)
A10: =IF(_LEITURA!$N10="","",INDEX(_LEITURA!$K$2:$K$1201,_LEITURA!$N10)) | B10: =IF(_LEITURA!$N10="","",INDEX(_LEITURA!$E$2:$E$1201,_LEITURA!$N10)) | C10: =IF(_LEITURA!$N10="","",INDEX(_LEITURA!$J$2:$J$1201,_LEITURA!$N10)) | D10: =IF(_LEITURA!$N10="","",INDEX(_LEITURA!$G$2:$G$1201,_LEITURA!$N10)) | E10: =IF(B10="","",SUMIFS(INVENTÁRIO!$C$2:$C$801,INVENTÁRIO!$A$2:$A$801,B10)) | F10: =IF(B10="","",MAX(0,D10-E10)) | G10: =IF(B10="","",IF(COUNTIFS($B$2:$B$1201,B10,$A$2:$A$1201,"<>"&A10)>0,"Sim","")) | H10: =IF(N(F10)>0,MAX(H$1:H9)+1,"") | I10: =IF(B10="","",IF(INDEX($C$2:$C$1201,MATCH(B10,$B$2:$B$1201,0))<>C10,"Nome diferente em outro deck — revisar","")) | J10: =IF(AND(B10<>"",A10=BULK!$A$1,N(F10)>0),MAX(J$1:J9)+1,"") | K10: =IF(B10="","",IFERROR(LEFT(B10,FIND("-",B10)-1),B10)) | L10: =IF(K10="","",IF(ISNUMBER(--MID(K10,1,1)),0,IF(ISNUMBER(--MID(K10,2,1)),1,IF(ISNUMBER(--MID(K10,3,1)),2,IF(ISNUMBER(--MID(K10,4,1)),3,MIN(LEN(K10),4)))))) | M10: =IF(B10="","",LEFT(K10,L10)&REPT("0",4-L10)&RIGHT("000"&IFERROR(VALUE(MID(K10,L10+1,9)),0),3)&RIGHT("0000"&IFERROR(VALUE(MID(B10,FIND("-",B10)+1,9)),0),4)) | N10: =IF(OR(B10="",N(F10)<=0),"",IF('FALTAS POR DECK'!$P$1="Código","K"&M10&RIGHT("00000"&ROW(),5),IF('FALTAS POR DECK'!$P$1="Nome","K"&UPPER(SUBSTITUTE(SUBSTITUTE(SUBSTITUTE(C10,"*",""),"?",""),"~",""))&"0"&M10&RIGHT("00000"&ROW(),5),IF('FALTAS POR DECK'!$P$1="Falta (maior primeiro)","K"&RIGHT("0000"&(9999-F10),4)&M10&RIGHT("00000"&ROW(),5),IF('FALTAS POR DECK'!$P$1="Deck e código","K"&RIGHT("00"&IFERROR(MATCH(A10,_LEITURA!$P$2:$P$21,0),99),2)&M10&RIGHT("00000"&ROW(),5),"K"&RIGHT("00000"&ROW(),5)))))) | O10: =IF(N10="","",COUNTIFS($N$2:$N$1201,"<"&N10,$F$2:$F$1201,">0")+1)
A11: =IF(_LEITURA!$N11="","",INDEX(_LEITURA!$K$2:$K$1201,_LEITURA!$N11)) | B11: =IF(_LEITURA!$N11="","",INDEX(_LEITURA!$E$2:$E$1201,_LEITURA!$N11)) | C11: =IF(_LEITURA!$N11="","",INDEX(_LEITURA!$J$2:$J$1201,_LEITURA!$N11)) | D11: =IF(_LEITURA!$N11="","",INDEX(_LEITURA!$G$2:$G$1201,_LEITURA!$N11)) | E11: =IF(B11="","",SUMIFS(INVENTÁRIO!$C$2:$C$801,INVENTÁRIO!$A$2:$A$801,B11)) | F11: =IF(B11="","",MAX(0,D11-E11)) | G11: =IF(B11="","",IF(COUNTIFS($B$2:$B$1201,B11,$A$2:$A$1201,"<>"&A11)>0,"Sim","")) | H11: =IF(N(F11)>0,MAX(H$1:H10)+1,"") | I11: =IF(B11="","",IF(INDEX($C$2:$C$1201,MATCH(B11,$B$2:$B$1201,0))<>C11,"Nome diferente em outro deck — revisar","")) | J11: =IF(AND(B11<>"",A11=BULK!$A$1,N(F11)>0),MAX(J$1:J10)+1,"") | K11: =IF(B11="","",IFERROR(LEFT(B11,FIND("-",B11)-1),B11)) | L11: =IF(K11="","",IF(ISNUMBER(--MID(K11,1,1)),0,IF(ISNUMBER(--MID(K11,2,1)),1,IF(ISNUMBER(--MID(K11,3,1)),2,IF(ISNUMBER(--MID(K11,4,1)),3,MIN(LEN(K11),4)))))) | M11: =IF(B11="","",LEFT(K11,L11)&REPT("0",4-L11)&RIGHT("000"&IFERROR(VALUE(MID(K11,L11+1,9)),0),3)&RIGHT("0000"&IFERROR(VALUE(MID(B11,FIND("-",B11)+1,9)),0),4)) | N11: =IF(OR(B11="",N(F11)<=0),"",IF('FALTAS POR DECK'!$P$1="Código","K"&M11&RIGHT("00000"&ROW(),5),IF('FALTAS POR DECK'!$P$1="Nome","K"&UPPER(SUBSTITUTE(SUBSTITUTE(SUBSTITUTE(C11,"*",""),"?",""),"~",""))&"0"&M11&RIGHT("00000"&ROW(),5),IF('FALTAS POR DECK'!$P$1="Falta (maior primeiro)","K"&RIGHT("0000"&(9999-F11),4)&M11&RIGHT("00000"&ROW(),5),IF('FALTAS POR DECK'!$P$1="Deck e código","K"&RIGHT("00"&IFERROR(MATCH(A11,_LEITURA!$P$2:$P$21,0),99),2)&M11&RIGHT("00000"&ROW(),5),"K"&RIGHT("00000"&ROW(),5)))))) | O11: =IF(N11="","",COUNTIFS($N$2:$N$1201,"<"&N11,$F$2:$F$1201,">0")+1)
A12: =IF(_LEITURA!$N12="","",INDEX(_LEITURA!$K$2:$K$1201,_LEITURA!$N12)) | B12: =IF(_LEITURA!$N12="","",INDEX(_LEITURA!$E$2:$E$1201,_LEITURA!$N12)) | C12: =IF(_LEITURA!$N12="","",INDEX(_LEITURA!$J$2:$J$1201,_LEITURA!$N12)) | D12: =IF(_LEITURA!$N12="","",INDEX(_LEITURA!$G$2:$G$1201,_LEITURA!$N12)) | E12: =IF(B12="","",SUMIFS(INVENTÁRIO!$C$2:$C$801,INVENTÁRIO!$A$2:$A$801,B12)) | F12: =IF(B12="","",MAX(0,D12-E12)) | G12: =IF(B12="","",IF(COUNTIFS($B$2:$B$1201,B12,$A$2:$A$1201,"<>"&A12)>0,"Sim","")) | H12: =IF(N(F12)>0,MAX(H$1:H11)+1,"") | I12: =IF(B12="","",IF(INDEX($C$2:$C$1201,MATCH(B12,$B$2:$B$1201,0))<>C12,"Nome diferente em outro deck — revisar","")) | J12: =IF(AND(B12<>"",A12=BULK!$A$1,N(F12)>0),MAX(J$1:J11)+1,"") | K12: =IF(B12="","",IFERROR(LEFT(B12,FIND("-",B12)-1),B12)) | L12: =IF(K12="","",IF(ISNUMBER(--MID(K12,1,1)),0,IF(ISNUMBER(--MID(K12,2,1)),1,IF(ISNUMBER(--MID(K12,3,1)),2,IF(ISNUMBER(--MID(K12,4,1)),3,MIN(LEN(K12),4)))))) | M12: =IF(B12="","",LEFT(K12,L12)&REPT("0",4-L12)&RIGHT("000"&IFERROR(VALUE(MID(K12,L12+1,9)),0),3)&RIGHT("0000"&IFERROR(VALUE(MID(B12,FIND("-",B12)+1,9)),0),4)) | N12: =IF(OR(B12="",N(F12)<=0),"",IF('FALTAS POR DECK'!$P$1="Código","K"&M12&RIGHT("00000"&ROW(),5),IF('FALTAS POR DECK'!$P$1="Nome","K"&UPPER(SUBSTITUTE(SUBSTITUTE(SUBSTITUTE(C12,"*",""),"?",""),"~",""))&"0"&M12&RIGHT("00000"&ROW(),5),IF('FALTAS POR DECK'!$P$1="Falta (maior primeiro)","K"&RIGHT("0000"&(9999-F12),4)&M12&RIGHT("00000"&ROW(),5),IF('FALTAS POR DECK'!$P$1="Deck e código","K"&RIGHT("00"&IFERROR(MATCH(A12,_LEITURA!$P$2:$P$21,0),99),2)&M12&RIGHT("00000"&ROW(),5),"K"&RIGHT("00000"&ROW(),5)))))) | O12: =IF(N12="","",COUNTIFS($N$2:$N$1201,"<"&N12,$F$2:$F$1201,">0")+1)
A13: =IF(_LEITURA!$N13="","",INDEX(_LEITURA!$K$2:$K$1201,_LEITURA!$N13)) | B13: =IF(_LEITURA!$N13="","",INDEX(_LEITURA!$E$2:$E$1201,_LEITURA!$N13)) | C13: =IF(_LEITURA!$N13="","",INDEX(_LEITURA!$J$2:$J$1201,_LEITURA!$N13)) | D13: =IF(_LEITURA!$N13="","",INDEX(_LEITURA!$G$2:$G$1201,_LEITURA!$N13)) | E13: =IF(B13="","",SUMIFS(INVENTÁRIO!$C$2:$C$801,INVENTÁRIO!$A$2:$A$801,B13)) | F13: =IF(B13="","",MAX(0,D13-E13)) | G13: =IF(B13="","",IF(COUNTIFS($B$2:$B$1201,B13,$A$2:$A$1201,"<>"&A13)>0,"Sim","")) | H13: =IF(N(F13)>0,MAX(H$1:H12)+1,"") | I13: =IF(B13="","",IF(INDEX($C$2:$C$1201,MATCH(B13,$B$2:$B$1201,0))<>C13,"Nome diferente em outro deck — revisar","")) | J13: =IF(AND(B13<>"",A13=BULK!$A$1,N(F13)>0),MAX(J$1:J12)+1,"") | K13: =IF(B13="","",IFERROR(LEFT(B13,FIND("-",B13)-1),B13)) | L13: =IF(K13="","",IF(ISNUMBER(--MID(K13,1,1)),0,IF(ISNUMBER(--MID(K13,2,1)),1,IF(ISNUMBER(--MID(K13,3,1)),2,IF(ISNUMBER(--MID(K13,4,1)),3,MIN(LEN(K13),4)))))) | M13: =IF(B13="","",LEFT(K13,L13)&REPT("0",4-L13)&RIGHT("000"&IFERROR(VALUE(MID(K13,L13+1,9)),0),3)&RIGHT("0000"&IFERROR(VALUE(MID(B13,FIND("-",B13)+1,9)),0),4)) | N13: =IF(OR(B13="",N(F13)<=0),"",IF('FALTAS POR DECK'!$P$1="Código","K"&M13&RIGHT("00000"&ROW(),5),IF('FALTAS POR DECK'!$P$1="Nome","K"&UPPER(SUBSTITUTE(SUBSTITUTE(SUBSTITUTE(C13,"*",""),"?",""),"~",""))&"0"&M13&RIGHT("00000"&ROW(),5),IF('FALTAS POR DECK'!$P$1="Falta (maior primeiro)","K"&RIGHT("0000"&(9999-F13),4)&M13&RIGHT("00000"&ROW(),5),IF('FALTAS POR DECK'!$P$1="Deck e código","K"&RIGHT("00"&IFERROR(MATCH(A13,_LEITURA!$P$2:$P$21,0),99),2)&M13&RIGHT("00000"&ROW(),5),"K"&RIGHT("00000"&ROW(),5)))))) | O13: =IF(N13="","",COUNTIFS($N$2:$N$1201,"<"&N13,$F$2:$F$1201,">0")+1)
... A1201: =IF(_LEITURA!$N1201="","",INDEX(_LEITURA!$K$2:$K$1201,_LEITURA!$N1201)) | B1201: =IF(_LEITURA!$N1201="","",INDEX(_LEITURA!$E$2:$E$1201,_LEITURA!$N1201)) | C1201: =IF(_LEITURA!$N1201="","",INDEX(_LEITURA!$J$2:$J$1201,_LEITURA!$N1201)) | D1201: =IF(_LEITURA!$N1201="","",INDEX(_LEITURA!$G$2:$G$1201,_LEITURA!$N1201)) | E1201: =IF(B1201="","",SUMIFS(INVENTÁRIO!$C$2:$C$801,INVENTÁRIO!$A$2:$A$801,B1201)) | F1201: =IF(B1201="","",MAX(0,D1201-E1201)) | G1201: =IF(B1201="","",IF(COUNTIFS($B$2:$B$1201,B1201,$A$2:$A$1201,"<>"&A1201)>0,"Sim","")) | H1201: =IF(N(F1201)>0,MAX(H$1:H1200)+1,"") | I1201: =IF(B1201="","",IF(INDEX($C$2:$C$1201,MATCH(B1201,$B$2:$B$1201,0))<>C1201,"Nome diferente em outro deck — revisar","")) | J1201: =IF(AND(B1201<>"",A1201=BULK!$A$1,N(F1201)>0),MAX(J$1:J1200)+1,"") | K1201: =IF(B1201="","",IFERROR(LEFT(B1201,FIND("-",B1201)-1),B1201)) | L1201: =IF(K1201="","",IF(ISNUMBER(--MID(K1201,1,1)),0,IF(ISNUMBER(--MID(K1201,2,1)),1,IF(ISNUMBER(--MID(K1201,3,1)),2,IF(ISNUMBER(--MID(K1201,4,1)),3,MIN(LEN(K1201),4)))))) | M1201: =IF(B1201="","",LEFT(K1201,L1201)&REPT("0",4-L1201)&RIGHT("000"&IFERROR(VALUE(MID(K1201,L1201+1,9)),0),3)&RIGHT("0000"&IFERROR(VALUE(MID(B1201,FIND("-",B1201)+1,9)),0),4)) | N1201: =IF(OR(B1201="",N(F1201)<=0),"",IF('FALTAS POR DECK'!$P$1="Código","K"&M1201&RIGHT("00000"&ROW(),5),IF('FALTAS POR DECK'!$P$1="Nome","K"&UPPER(SUBSTITUTE(SUBSTITUTE(SUBSTITUTE(C1201,"*",""),"?",""),"~",""))&"0"&M1201&RIGHT("00000"&ROW(),5),IF('FALTAS POR DECK'!$P$1="Falta (maior primeiro)","K"&RIGHT("0000"&(9999-F1201),4)&M1201&RIGHT("00000"&ROW(),5),IF('FALTAS POR DECK'!$P$1="Deck e código","K"&RIGHT("00"&IFERROR(MATCH(A1201,_LEITURA!$P$2:$P$21,0),99),2)&M1201&RIGHT("00000"&ROW(),5),"K"&RIGHT("00000"&ROW(),5)))))) | O1201: =IF(N1201="","",COUNTIFS($N$2:$N$1201,"<"&N1201,$F$2:$F$1201,">0")+1)

Sheet CONSOLIDADO
A1: Código | B1: Nome | C1: Tenho | D1: Necessidade Total (um deck por vez) | E1: Falta Total | F1: Status | G1: Nº de decks | H1: Compartilhada? | I1: Soma nos decks (todos ao mesmo tempo) | J1: Falta se montar todos ao mesmo tempo | K1: =IF(INDEX(_LEITURA!$Q$2:$Q$21,1)=1,"Nec. "&INDEX(_LEITURA!$P$2:$P$21,1),"") | L1: =IF(INDEX(_LEITURA!$Q$2:$Q$21,2)=1,"Nec. "&INDEX(_LEITURA!$P$2:$P$21,2),"") | M1: =IF(INDEX(_LEITURA!$Q$2:$Q$21,3)=1,"Nec. "&INDEX(_LEITURA!$P$2:$P$21,3),"") | N1: =IF(INDEX(_LEITURA!$Q$2:$Q$21,4)=1,"Nec. "&INDEX(_LEITURA!$P$2:$P$21,4),"") | O1: =IF(INDEX(_LEITURA!$Q$2:$Q$21,5)=1,"Nec. "&INDEX(_LEITURA!$P$2:$P$21,5),"") | P1: =IF(INDEX(_LEITURA!$Q$2:$Q$21,6)=1,"Nec. "&INDEX(_LEITURA!$P$2:$P$21,6),"") | Q1: =IF(INDEX(_LEITURA!$Q$2:$Q$21,7)=1,"Nec. "&INDEX(_LEITURA!$P$2:$P$21,7),"") | R1: =IF(INDEX(_LEITURA!$Q$2:$Q$21,8)=1,"Nec. "&INDEX(_LEITURA!$P$2:$P$21,8),"") | S1: =IF(INDEX(_LEITURA!$Q$2:$Q$21,9)=1,"Nec. "&INDEX(_LEITURA!$P$2:$P$21,9),"") | T1: =IF(INDEX(_LEITURA!$Q$2:$Q$21,10)=1,"Nec. "&INDEX(_LEITURA!$P$2:$P$21,10),"") | U1: =IF(INDEX(_LEITURA!$Q$2:$Q$21,11)=1,"Nec. "&INDEX(_LEITURA!$P$2:$P$21,11),"") | V1: =IF(INDEX(_LEITURA!$Q$2:$Q$21,12)=1,"Nec. "&INDEX(_LEITURA!$P$2:$P$21,12),"") | W1: =IF(INDEX(_LEITURA!$Q$2:$Q$21,13)=1,"Nec. "&INDEX(_LEITURA!$P$2:$P$21,13),"") | X1: =IF(INDEX(_LEITURA!$Q$2:$Q$21,14)=1,"Nec. "&INDEX(_LEITURA!$P$2:$P$21,14),"") | Y1: =IF(INDEX(_LEITURA!$Q$2:$Q$21,15)=1,"Nec. "&INDEX(_LEITURA!$P$2:$P$21,15),"") | Z1: =IF(INDEX(_LEITURA!$Q$2:$Q$21,16)=1,"Nec. "&INDEX(_LEITURA!$P$2:$P$21,16),"") | AA1: =IF(INDEX(_LEITURA!$Q$2:$Q$21,17)=1,"Nec. "&INDEX(_LEITURA!$P$2:$P$21,17),"") | AB1: =IF(INDEX(_LEITURA!$Q$2:$Q$21,18)=1,"Nec. "&INDEX(_LEITURA!$P$2:$P$21,18),"") | AC1: =IF(INDEX(_LEITURA!$Q$2:$Q$21,19)=1,"Nec. "&INDEX(_LEITURA!$P$2:$P$21,19),"") | AD1: =IF(INDEX(_LEITURA!$Q$2:$Q$21,20)=1,"Nec. "&INDEX(_LEITURA!$P$2:$P$21,20),"") | AE1: Seq. falta (aux) | AF1: Antes do hífen (aux) | AG1: Nº de letras (aux) | AH1: Chave do código (aux) | AI1: Chave de ordenação (aux) | AJ1: Posição na ordenação (aux) | AK1: Posição por código (aux, BULK) | AM1: RESUMO (todos os decks juntos)
A2: =IF(INVENTÁRIO!A2="","",INVENTÁRIO!A2) | B2: =IF(A2="","",INVENTÁRIO!B2) | C2: =IF(A2="","",INVENTÁRIO!C2) | D2: =IF(A2="","",MAX(K2:AD2)) | E2: =IF(A2="","",MAX(0,D2-C2)) | F2: =IF(A2="","",IF(D2=0,"Fora dos decks",IF(E2=0,"Completo","Falta"))) | G2: =IF(A2="","",COUNTIF(K2:AD2,">0")) | H2: =IF(A2="","",IF(G2>1,"Sim","")) | I2: =IF(A2="","",SUMIFS(DECKS!$D$2:$D$1201,DECKS!$B$2:$B$1201,A2)) | J2: =IF(A2="","",MAX(0,I2-C2)) | K2: =IF(OR($A2="",INDEX(_LEITURA!$Q$2:$Q$21,1)=0),"",SUMIFS(DECKS!$D$2:$D$1201,DECKS!$A$2:$A$1201,INDEX(_LEITURA!$P$2:$P$21,1),DECKS!$B$2:$B$1201,$A2)) | L2: =IF(OR($A2="",INDEX(_LEITURA!$Q$2:$Q$21,2)=0),"",SUMIFS(DECKS!$D$2:$D$1201,DECKS!$A$2:$A$1201,INDEX(_LEITURA!$P$2:$P$21,2),DECKS!$B$2:$B$1201,$A2)) | M2: =IF(OR($A2="",INDEX(_LEITURA!$Q$2:$Q$21,3)=0),"",SUMIFS(DECKS!$D$2:$D$1201,DECKS!$A$2:$A$1201,INDEX(_LEITURA!$P$2:$P$21,3),DECKS!$B$2:$B$1201,$A2)) | N2: =IF(OR($A2="",INDEX(_LEITURA!$Q$2:$Q$21,4)=0),"",SUMIFS(DECKS!$D$2:$D$1201,DECKS!$A$2:$A$1201,INDEX(_LEITURA!$P$2:$P$21,4),DECKS!$B$2:$B$1201,$A2)) | O2: =IF(OR($A2="",INDEX(_LEITURA!$Q$2:$Q$21,5)=0),"",SUMIFS(DECKS!$D$2:$D$1201,DECKS!$A$2:$A$1201,INDEX(_LEITURA!$P$2:$P$21,5),DECKS!$B$2:$B$1201,$A2)) | P2: =IF(OR($A2="",INDEX(_LEITURA!$Q$2:$Q$21,6)=0),"",SUMIFS(DECKS!$D$2:$D$1201,DECKS!$A$2:$A$1201,INDEX(_LEITURA!$P$2:$P$21,6),DECKS!$B$2:$B$1201,$A2)) | Q2: =IF(OR($A2="",INDEX(_LEITURA!$Q$2:$Q$21,7)=0),"",SUMIFS(DECKS!$D$2:$D$1201,DECKS!$A$2:$A$1201,INDEX(_LEITURA!$P$2:$P$21,7),DECKS!$B$2:$B$1201,$A2)) | R2: =IF(OR($A2="",INDEX(_LEITURA!$Q$2:$Q$21,8)=0),"",SUMIFS(DECKS!$D$2:$D$1201,DECKS!$A$2:$A$1201,INDEX(_LEITURA!$P$2:$P$21,8),DECKS!$B$2:$B$1201,$A2)) | S2: =IF(OR($A2="",INDEX(_LEITURA!$Q$2:$Q$21,9)=0),"",SUMIFS(DECKS!$D$2:$D$1201,DECKS!$A$2:$A$1201,INDEX(_LEITURA!$P$2:$P$21,9),DECKS!$B$2:$B$1201,$A2)) | T2: =IF(OR($A2="",INDEX(_LEITURA!$Q$2:$Q$21,10)=0),"",SUMIFS(DECKS!$D$2:$D$1201,DECKS!$A$2:$A$1201,INDEX(_LEITURA!$P$2:$P$21,10),DECKS!$B$2:$B$1201,$A2)) | U2: =IF(OR($A2="",INDEX(_LEITURA!$Q$2:$Q$21,11)=0),"",SUMIFS(DECKS!$D$2:$D$1201,DECKS!$A$2:$A$1201,INDEX(_LEITURA!$P$2:$P$21,11),DECKS!$B$2:$B$1201,$A2)) | V2: =IF(OR($A2="",INDEX(_LEITURA!$Q$2:$Q$21,12)=0),"",SUMIFS(DECKS!$D$2:$D$1201,DECKS!$A$2:$A$1201,INDEX(_LEITURA!$P$2:$P$21,12),DECKS!$B$2:$B$1201,$A2)) | W2: =IF(OR($A2="",INDEX(_LEITURA!$Q$2:$Q$21,13)=0),"",SUMIFS(DECKS!$D$2:$D$1201,DECKS!$A$2:$A$1201,INDEX(_LEITURA!$P$2:$P$21,13),DECKS!$B$2:$B$1201,$A2)) | X2: =IF(OR($A2="",INDEX(_LEITURA!$Q$2:$Q$21,14)=0),"",SUMIFS(DECKS!$D$2:$D$1201,DECKS!$A$2:$A$1201,INDEX(_LEITURA!$P$2:$P$21,14),DECKS!$B$2:$B$1201,$A2)) | Y2: =IF(OR($A2="",INDEX(_LEITURA!$Q$2:$Q$21,15)=0),"",SUMIFS(DECKS!$D$2:$D$1201,DECKS!$A$2:$A$1201,INDEX(_LEITURA!$P$2:$P$21,15),DECKS!$B$2:$B$1201,$A2)) | Z2: =IF(OR($A2="",INDEX(_LEITURA!$Q$2:$Q$21,16)=0),"",SUMIFS(DECKS!$D$2:$D$1201,DECKS!$A$2:$A$1201,INDEX(_LEITURA!$P$2:$P$21,16),DECKS!$B$2:$B$1201,$A2)) | AA2: =IF(OR($A2="",INDEX(_LEITURA!$Q$2:$Q$21,17)=0),"",SUMIFS(DECKS!$D$2:$D$1201,DECKS!$A$2:$A$1201,INDEX(_LEITURA!$P$2:$P$21,17),DECKS!$B$2:$B$1201,$A2)) | AB2: =IF(OR($A2="",INDEX(_LEITURA!$Q$2:$Q$21,18)=0),"",SUMIFS(DECKS!$D$2:$D$1201,DECKS!$A$2:$A$1201,INDEX(_LEITURA!$P$2:$P$21,18),DECKS!$B$2:$B$1201,$A2)) | AC2: =IF(OR($A2="",INDEX(_LEITURA!$Q$2:$Q$21,19)=0),"",SUMIFS(DECKS!$D$2:$D$1201,DECKS!$A$2:$A$1201,INDEX(_LEITURA!$P$2:$P$21,19),DECKS!$B$2:$B$1201,$A2)) | AD2: =IF(OR($A2="",INDEX(_LEITURA!$Q$2:$Q$21,20)=0),"",SUMIFS(DECKS!$D$2:$D$1201,DECKS!$A$2:$A$1201,INDEX(_LEITURA!$P$2:$P$21,20),DECKS!$B$2:$B$1201,$A2)) | AE2: =IF(N(E2)>0,MAX(AE$1:AE1)+1,"") | AF2: =IF(A2="","",IFERROR(LEFT(A2,FIND("-",A2)-1),A2)) | AG2: =IF(AF2="","",IF(ISNUMBER(--MID(AF2,1,1)),0,IF(ISNUMBER(--MID(AF2,2,1)),1,IF(ISNUMBER(--MID(AF2,3,1)),2,IF(ISNUMBER(--MID(AF2,4,1)),3,MIN(LEN(AF2),4)))))) | AH2: =IF(A2="","",LEFT(AF2,AG2)&REPT("0",4-AG2)&RIGHT("000"&IFERROR(VALUE(MID(AF2,AG2+1,9)),0),3)&RIGHT("0000"&IFERROR(VALUE(MID(A2,FIND("-",A2)+1,9)),0),4)) | AI2: =IF(OR(A2="",N(E2)<=0),"",IF('FALTAS GERAL'!$M$1="Código","K"&AH2&RIGHT("00000"&ROW(),5),IF('FALTAS GERAL'!$M$1="Nome","K"&UPPER(SUBSTITUTE(SUBSTITUTE(SUBSTITUTE(B2,"*",""),"?",""),"~",""))&"0"&AH2&RIGHT("00000"&ROW(),5),IF('FALTAS GERAL'!$M$1="Falta (maior primeiro)","K"&RIGHT("0000"&(9999-E2),4)&AH2&RIGHT("00000"&ROW(),5),IF('FALTAS GERAL'!$M$1="Nº de decks (maior primeiro)","K"&RIGHT("00"&(99-N(G2)),2)&AH2&RIGHT("00000"&ROW(),5),"K"&RIGHT("00000"&ROW(),5)))))) | AJ2: =IF(AI2="","",COUNTIFS($AI$2:$AI$801,"<"&AI2,$E$2:$E$801,">0")+1) | AK2: =IF(OR(A2="",N(E2)<=0),"",COUNTIFS($AH$2:$AH$801,"<"&AH2,$E$2:$E$801,">0")+COUNTIFS($AH$2:AH2,AH2,$E$2:E2,">0")) | AM2: Cartas únicas | AN2: =COUNTIF(A2:A801,"?*") -> 0
A3: =IF(INVENTÁRIO!A3="","",INVENTÁRIO!A3) | B3: =IF(A3="","",INVENTÁRIO!B3) | C3: =IF(A3="","",INVENTÁRIO!C3) | D3: =IF(A3="","",MAX(K3:AD3)) | E3: =IF(A3="","",MAX(0,D3-C3)) | F3: =IF(A3="","",IF(D3=0,"Fora dos decks",IF(E3=0,"Completo","Falta"))) | G3: =IF(A3="","",COUNTIF(K3:AD3,">0")) | H3: =IF(A3="","",IF(G3>1,"Sim","")) | I3: =IF(A3="","",SUMIFS(DECKS!$D$2:$D$1201,DECKS!$B$2:$B$1201,A3)) | J3: =IF(A3="","",MAX(0,I3-C3)) | K3: =IF(OR($A3="",INDEX(_LEITURA!$Q$2:$Q$21,1)=0),"",SUMIFS(DECKS!$D$2:$D$1201,DECKS!$A$2:$A$1201,INDEX(_LEITURA!$P$2:$P$21,1),DECKS!$B$2:$B$1201,$A3)) | L3: =IF(OR($A3="",INDEX(_LEITURA!$Q$2:$Q$21,2)=0),"",SUMIFS(DECKS!$D$2:$D$1201,DECKS!$A$2:$A$1201,INDEX(_LEITURA!$P$2:$P$21,2),DECKS!$B$2:$B$1201,$A3)) | M3: =IF(OR($A3="",INDEX(_LEITURA!$Q$2:$Q$21,3)=0),"",SUMIFS(DECKS!$D$2:$D$1201,DECKS!$A$2:$A$1201,INDEX(_LEITURA!$P$2:$P$21,3),DECKS!$B$2:$B$1201,$A3)) | N3: =IF(OR($A3="",INDEX(_LEITURA!$Q$2:$Q$21,4)=0),"",SUMIFS(DECKS!$D$2:$D$1201,DECKS!$A$2:$A$1201,INDEX(_LEITURA!$P$2:$P$21,4),DECKS!$B$2:$B$1201,$A3)) | O3: =IF(OR($A3="",INDEX(_LEITURA!$Q$2:$Q$21,5)=0),"",SUMIFS(DECKS!$D$2:$D$1201,DECKS!$A$2:$A$1201,INDEX(_LEITURA!$P$2:$P$21,5),DECKS!$B$2:$B$1201,$A3)) | P3: =IF(OR($A3="",INDEX(_LEITURA!$Q$2:$Q$21,6)=0),"",SUMIFS(DECKS!$D$2:$D$1201,DECKS!$A$2:$A$1201,INDEX(_LEITURA!$P$2:$P$21,6),DECKS!$B$2:$B$1201,$A3)) | Q3: =IF(OR($A3="",INDEX(_LEITURA!$Q$2:$Q$21,7)=0),"",SUMIFS(DECKS!$D$2:$D$1201,DECKS!$A$2:$A$1201,INDEX(_LEITURA!$P$2:$P$21,7),DECKS!$B$2:$B$1201,$A3)) | R3: =IF(OR($A3="",INDEX(_LEITURA!$Q$2:$Q$21,8)=0),"",SUMIFS(DECKS!$D$2:$D$1201,DECKS!$A$2:$A$1201,INDEX(_LEITURA!$P$2:$P$21,8),DECKS!$B$2:$B$1201,$A3)) | S3: =IF(OR($A3="",INDEX(_LEITURA!$Q$2:$Q$21,9)=0),"",SUMIFS(DECKS!$D$2:$D$1201,DECKS!$A$2:$A$1201,INDEX(_LEITURA!$P$2:$P$21,9),DECKS!$B$2:$B$1201,$A3)) | T3: =IF(OR($A3="",INDEX(_LEITURA!$Q$2:$Q$21,10)=0),"",SUMIFS(DECKS!$D$2:$D$1201,DECKS!$A$2:$A$1201,INDEX(_LEITURA!$P$2:$P$21,10),DECKS!$B$2:$B$1201,$A3)) | U3: =IF(OR($A3="",INDEX(_LEITURA!$Q$2:$Q$21,11)=0),"",SUMIFS(DECKS!$D$2:$D$1201,DECKS!$A$2:$A$1201,INDEX(_LEITURA!$P$2:$P$21,11),DECKS!$B$2:$B$1201,$A3)) | V3: =IF(OR($A3="",INDEX(_LEITURA!$Q$2:$Q$21,12)=0),"",SUMIFS(DECKS!$D$2:$D$1201,DECKS!$A$2:$A$1201,INDEX(_LEITURA!$P$2:$P$21,12),DECKS!$B$2:$B$1201,$A3)) | W3: =IF(OR($A3="",INDEX(_LEITURA!$Q$2:$Q$21,13)=0),"",SUMIFS(DECKS!$D$2:$D$1201,DECKS!$A$2:$A$1201,INDEX(_LEITURA!$P$2:$P$21,13),DECKS!$B$2:$B$1201,$A3)) | X3: =IF(OR($A3="",INDEX(_LEITURA!$Q$2:$Q$21,14)=0),"",SUMIFS(DECKS!$D$2:$D$1201,DECKS!$A$2:$A$1201,INDEX(_LEITURA!$P$2:$P$21,14),DECKS!$B$2:$B$1201,$A3)) | Y3: =IF(OR($A3="",INDEX(_LEITURA!$Q$2:$Q$21,15)=0),"",SUMIFS(DECKS!$D$2:$D$1201,DECKS!$A$2:$A$1201,INDEX(_LEITURA!$P$2:$P$21,15),DECKS!$B$2:$B$1201,$A3)) | Z3: =IF(OR($A3="",INDEX(_LEITURA!$Q$2:$Q$21,16)=0),"",SUMIFS(DECKS!$D$2:$D$1201,DECKS!$A$2:$A$1201,INDEX(_LEITURA!$P$2:$P$21,16),DECKS!$B$2:$B$1201,$A3)) | AA3: =IF(OR($A3="",INDEX(_LEITURA!$Q$2:$Q$21,17)=0),"",SUMIFS(DECKS!$D$2:$D$1201,DECKS!$A$2:$A$1201,INDEX(_LEITURA!$P$2:$P$21,17),DECKS!$B$2:$B$1201,$A3)) | AB3: =IF(OR($A3="",INDEX(_LEITURA!$Q$2:$Q$21,18)=0),"",SUMIFS(DECKS!$D$2:$D$1201,DECKS!$A$2:$A$1201,INDEX(_LEITURA!$P$2:$P$21,18),DECKS!$B$2:$B$1201,$A3)) | AC3: =IF(OR($A3="",INDEX(_LEITURA!$Q$2:$Q$21,19)=0),"",SUMIFS(DECKS!$D$2:$D$1201,DECKS!$A$2:$A$1201,INDEX(_LEITURA!$P$2:$P$21,19),DECKS!$B$2:$B$1201,$A3)) | AD3: =IF(OR($A3="",INDEX(_LEITURA!$Q$2:$Q$21,20)=0),"",SUMIFS(DECKS!$D$2:$D$1201,DECKS!$A$2:$A$1201,INDEX(_LEITURA!$P$2:$P$21,20),DECKS!$B$2:$B$1201,$A3)) | AE3: =IF(N(E3)>0,MAX(AE$1:AE2)+1,"") | AF3: =IF(A3="","",IFERROR(LEFT(A3,FIND("-",A3)-1),A3)) | AG3: =IF(AF3="","",IF(ISNUMBER(--MID(AF3,1,1)),0,IF(ISNUMBER(--MID(AF3,2,1)),1,IF(ISNUMBER(--MID(AF3,3,1)),2,IF(ISNUMBER(--MID(AF3,4,1)),3,MIN(LEN(AF3),4)))))) | AH3: =IF(A3="","",LEFT(AF3,AG3)&REPT("0",4-AG3)&RIGHT("000"&IFERROR(VALUE(MID(AF3,AG3+1,9)),0),3)&RIGHT("0000"&IFERROR(VALUE(MID(A3,FIND("-",A3)+1,9)),0),4)) | AI3: =IF(OR(A3="",N(E3)<=0),"",IF('FALTAS GERAL'!$M$1="Código","K"&AH3&RIGHT("00000"&ROW(),5),IF('FALTAS GERAL'!$M$1="Nome","K"&UPPER(SUBSTITUTE(SUBSTITUTE(SUBSTITUTE(B3,"*",""),"?",""),"~",""))&"0"&AH3&RIGHT("00000"&ROW(),5),IF('FALTAS GERAL'!$M$1="Falta (maior primeiro)","K"&RIGHT("0000"&(9999-E3),4)&AH3&RIGHT("00000"&ROW(),5),IF('FALTAS GERAL'!$M$1="Nº de decks (maior primeiro)","K"&RIGHT("00"&(99-N(G3)),2)&AH3&RIGHT("00000"&ROW(),5),"K"&RIGHT("00000"&ROW(),5)))))) | AJ3: =IF(AI3="","",COUNTIFS($AI$2:$AI$801,"<"&AI3,$E$2:$E$801,">0")+1) | AK3: =IF(OR(A3="",N(E3)<=0),"",COUNTIFS($AH$2:$AH$801,"<"&AH3,$E$2:$E$801,">0")+COUNTIFS($AH$2:AH3,AH3,$E$2:E3,">0")) | AM3: Cartas únicas que faltam | AN3: =COUNTIF(F2:F801,"Falta") -> 0
A4: =IF(INVENTÁRIO!A4="","",INVENTÁRIO!A4) | B4: =IF(A4="","",INVENTÁRIO!B4) | C4: =IF(A4="","",INVENTÁRIO!C4) | D4: =IF(A4="","",MAX(K4:AD4)) | E4: =IF(A4="","",MAX(0,D4-C4)) | F4: =IF(A4="","",IF(D4=0,"Fora dos decks",IF(E4=0,"Completo","Falta"))) | G4: =IF(A4="","",COUNTIF(K4:AD4,">0")) | H4: =IF(A4="","",IF(G4>1,"Sim","")) | I4: =IF(A4="","",SUMIFS(DECKS!$D$2:$D$1201,DECKS!$B$2:$B$1201,A4)) | J4: =IF(A4="","",MAX(0,I4-C4)) | K4: =IF(OR($A4="",INDEX(_LEITURA!$Q$2:$Q$21,1)=0),"",SUMIFS(DECKS!$D$2:$D$1201,DECKS!$A$2:$A$1201,INDEX(_LEITURA!$P$2:$P$21,1),DECKS!$B$2:$B$1201,$A4)) | L4: =IF(OR($A4="",INDEX(_LEITURA!$Q$2:$Q$21,2)=0),"",SUMIFS(DECKS!$D$2:$D$1201,DECKS!$A$2:$A$1201,INDEX(_LEITURA!$P$2:$P$21,2),DECKS!$B$2:$B$1201,$A4)) | M4: =IF(OR($A4="",INDEX(_LEITURA!$Q$2:$Q$21,3)=0),"",SUMIFS(DECKS!$D$2:$D$1201,DECKS!$A$2:$A$1201,INDEX(_LEITURA!$P$2:$P$21,3),DECKS!$B$2:$B$1201,$A4)) | N4: =IF(OR($A4="",INDEX(_LEITURA!$Q$2:$Q$21,4)=0),"",SUMIFS(DECKS!$D$2:$D$1201,DECKS!$A$2:$A$1201,INDEX(_LEITURA!$P$2:$P$21,4),DECKS!$B$2:$B$1201,$A4)) | O4: =IF(OR($A4="",INDEX(_LEITURA!$Q$2:$Q$21,5)=0),"",SUMIFS(DECKS!$D$2:$D$1201,DECKS!$A$2:$A$1201,INDEX(_LEITURA!$P$2:$P$21,5),DECKS!$B$2:$B$1201,$A4)) | P4: =IF(OR($A4="",INDEX(_LEITURA!$Q$2:$Q$21,6)=0),"",SUMIFS(DECKS!$D$2:$D$1201,DECKS!$A$2:$A$1201,INDEX(_LEITURA!$P$2:$P$21,6),DECKS!$B$2:$B$1201,$A4)) | Q4: =IF(OR($A4="",INDEX(_LEITURA!$Q$2:$Q$21,7)=0),"",SUMIFS(DECKS!$D$2:$D$1201,DECKS!$A$2:$A$1201,INDEX(_LEITURA!$P$2:$P$21,7),DECKS!$B$2:$B$1201,$A4)) | R4: =IF(OR($A4="",INDEX(_LEITURA!$Q$2:$Q$21,8)=0),"",SUMIFS(DECKS!$D$2:$D$1201,DECKS!$A$2:$A$1201,INDEX(_LEITURA!$P$2:$P$21,8),DECKS!$B$2:$B$1201,$A4)) | S4: =IF(OR($A4="",INDEX(_LEITURA!$Q$2:$Q$21,9)=0),"",SUMIFS(DECKS!$D$2:$D$1201,DECKS!$A$2:$A$1201,INDEX(_LEITURA!$P$2:$P$21,9),DECKS!$B$2:$B$1201,$A4)) | T4: =IF(OR($A4="",INDEX(_LEITURA!$Q$2:$Q$21,10)=0),"",SUMIFS(DECKS!$D$2:$D$1201,DECKS!$A$2:$A$1201,INDEX(_LEITURA!$P$2:$P$21,10),DECKS!$B$2:$B$1201,$A4)) | U4: =IF(OR($A4="",INDEX(_LEITURA!$Q$2:$Q$21,11)=0),"",SUMIFS(DECKS!$D$2:$D$1201,DECKS!$A$2:$A$1201,INDEX(_LEITURA!$P$2:$P$21,11),DECKS!$B$2:$B$1201,$A4)) | V4: =IF(OR($A4="",INDEX(_LEITURA!$Q$2:$Q$21,12)=0),"",SUMIFS(DECKS!$D$2:$D$1201,DECKS!$A$2:$A$1201,INDEX(_LEITURA!$P$2:$P$21,12),DECKS!$B$2:$B$1201,$A4)) | W4: =IF(OR($A4="",INDEX(_LEITURA!$Q$2:$Q$21,13)=0),"",SUMIFS(DECKS!$D$2:$D$1201,DECKS!$A$2:$A$1201,INDEX(_LEITURA!$P$2:$P$21,13),DECKS!$B$2:$B$1201,$A4)) | X4: =IF(OR($A4="",INDEX(_LEITURA!$Q$2:$Q$21,14)=0),"",SUMIFS(DECKS!$D$2:$D$1201,DECKS!$A$2:$A$1201,INDEX(_LEITURA!$P$2:$P$21,14),DECKS!$B$2:$B$1201,$A4)) | Y4: =IF(OR($A4="",INDEX(_LEITURA!$Q$2:$Q$21,15)=0),"",SUMIFS(DECKS!$D$2:$D$1201,DECKS!$A$2:$A$1201,INDEX(_LEITURA!$P$2:$P$21,15),DECKS!$B$2:$B$1201,$A4)) | Z4: =IF(OR($A4="",INDEX(_LEITURA!$Q$2:$Q$21,16)=0),"",SUMIFS(DECKS!$D$2:$D$1201,DECKS!$A$2:$A$1201,INDEX(_LEITURA!$P$2:$P$21,16),DECKS!$B$2:$B$1201,$A4)) | AA4: =IF(OR($A4="",INDEX(_LEITURA!$Q$2:$Q$21,17)=0),"",SUMIFS(DECKS!$D$2:$D$1201,DECKS!$A$2:$A$1201,INDEX(_LEITURA!$P$2:$P$21,17),DECKS!$B$2:$B$1201,$A4)) | AB4: =IF(OR($A4="",INDEX(_LEITURA!$Q$2:$Q$21,18)=0),"",SUMIFS(DECKS!$D$2:$D$1201,DECKS!$A$2:$A$1201,INDEX(_LEITURA!$P$2:$P$21,18),DECKS!$B$2:$B$1201,$A4)) | AC4: =IF(OR($A4="",INDEX(_LEITURA!$Q$2:$Q$21,19)=0),"",SUMIFS(DECKS!$D$2:$D$1201,DECKS!$A$2:$A$1201,INDEX(_LEITURA!$P$2:$P$21,19),DECKS!$B$2:$B$1201,$A4)) | AD4: =IF(OR($A4="",INDEX(_LEITURA!$Q$2:$Q$21,20)=0),"",SUMIFS(DECKS!$D$2:$D$1201,DECKS!$A$2:$A$1201,INDEX(_LEITURA!$P$2:$P$21,20),DECKS!$B$2:$B$1201,$A4)) | AE4: =IF(N(E4)>0,MAX(AE$1:AE3)+1,"") | AF4: =IF(A4="","",IFERROR(LEFT(A4,FIND("-",A4)-1),A4)) | AG4: =IF(AF4="","",IF(ISNUMBER(--MID(AF4,1,1)),0,IF(ISNUMBER(--MID(AF4,2,1)),1,IF(ISNUMBER(--MID(AF4,3,1)),2,IF(ISNUMBER(--MID(AF4,4,1)),3,MIN(LEN(AF4),4)))))) | AH4: =IF(A4="","",LEFT(AF4,AG4)&REPT("0",4-AG4)&RIGHT("000"&IFERROR(VALUE(MID(AF4,AG4+1,9)),0),3)&RIGHT("0000"&IFERROR(VALUE(MID(A4,FIND("-",A4)+1,9)),0),4)) | AI4: =IF(OR(A4="",N(E4)<=0),"",IF('FALTAS GERAL'!$M$1="Código","K"&AH4&RIGHT("00000"&ROW(),5),IF('FALTAS GERAL'!$M$1="Nome","K"&UPPER(SUBSTITUTE(SUBSTITUTE(SUBSTITUTE(B4,"*",""),"?",""),"~",""))&"0"&AH4&RIGHT("00000"&ROW(),5),IF('FALTAS GERAL'!$M$1="Falta (maior primeiro)","K"&RIGHT("0000"&(9999-E4),4)&AH4&RIGHT("00000"&ROW(),5),IF('FALTAS GERAL'!$M$1="Nº de decks (maior primeiro)","K"&RIGHT("00"&(99-N(G4)),2)&AH4&RIGHT("00000"&ROW(),5),"K"&RIGHT("00000"&ROW(),5)))))) | AJ4: =IF(AI4="","",COUNTIFS($AI$2:$AI$801,"<"&AI4,$E$2:$E$801,">0")+1) | AK4: =IF(OR(A4="",N(E4)<=0),"",COUNTIFS($AH$2:$AH$801,"<"&AH4,$E$2:$E$801,">0")+COUNTIFS($AH$2:AH4,AH4,$E$2:E4,">0")) | AM4: Cópias que faltam (um deck por vez) | AN4: =SUM(E2:E801) -> 0
